Workbook

Sheet 0. Hướng dẫn
A1: FILE KHO OXYMECIE — theo LÔ
A2: Nhập theo lô → xuất trừ kho theo lô → tự ra giá vốn từng hợp đồng.
B4: CÁCH TRỪ KHO
B5: Nguyên tắc | C5: Mỗi DÒNG hóa đơn = một LÔ, có mã riêng (L259-05). Xuất bao nhiêu thì ghi một dòng ở sheet "2. XuatKho".
B6: Ví dụ | C6: Lô L259-05 nhập 12 bình O2 8L. Xuất 1 bình cho HĐ A → ghi 1 dòng. Xuất 2 bình cho HĐ B → ghi 1 dòng nữa. Tồn còn 9.
B7: Giá vốn | C7: Tự lấy đơn giá của đúng lô đó. Không dùng bình quân — vì cùng mặt hàng giá các lô chênh nhau nhiều lần.
B8: Chặn xuất quá tồn | C8: Sheet "3. TonTheoLo" có cột cảnh báo nếu xuất nhiều hơn nhập.
B10: TÊN HÀNG KHÁC NHAU GIỮA HÓA ĐƠN VÀ HỢP ĐỒNG
B11: Vấn đề | C11: Hóa đơn ghi "Khí chuẩn Nitrogen dioxide (0.01%)", hợp đồng ghi "Bình khí chuẩn NO2 200ppm". Khác nồng độ = khác hàng.
B12: Cách xử lý | C12: Sheet "5. AnhXaTenBan" liệt kê 270 tên đang dùng trong hợp đồng bán. Anh gán mỗi tên về một LÔ hoặc một MÃ HÀNG.
B13: Vì sao phải tay | C13: Nồng độ ghi tự do (0.1 / 100ppm / 650mg/Nm3 / 99.99%) nên máy không tự khớp được. Chỉ người biết bình nào dùng cho đơn nào.
B14: Mẹo | C14: Gán xong một lần thì lần sau ở sheet "2. XuatKho" chỉ cần chọn lô, không phải nghĩ lại.
B16: QUY ƯỚC MÀU
B17: Vàng | C17: Ô anh nhập
B18: Xanh lá | C18: Em điền sẵn từ hóa đơn
B19: Xám | C19: Công thức
B20: Cam | C20: Cảnh báo
B22: DUNG DỊCH CHUẨN — MÃ RIÊNG THEO CHỈ TIÊU
B23: 4 mã riêng | C23: DD-PH (pH 4/7/10) · DD-AMONI (NH4 / NH4-N / Amoni) · DD-COD · DD-TSS. Còn DD-KHAC chỉ dùng cho dung dịch lẻ như NO3.
B24: Mỗi lần nhập một giá | C24: Mỗi dòng ở "1. NhapKho" là một LÔ riêng, có đơn giá riêng. Cùng mã DD-COD nhập 3 lần 3 giá → 3 lô, xuất trừ đúng lô nào giá đó.
B25: Nồng độ ghi ở đâu | C25: Ghi vào cột "Quy cách / nồng độ theo hóa đơn" của dòng nhập (VD: COD 50ppm, pH 7, NH4-N 10ppm). Không tách thành mã riêng cho từng nồng độ.
B26: ĐVT | C26: Dung dịch tính theo Chai 500ml, không phải Bình.

Sheet DM. Mã hàng
A1: DANH MỤC MÃ HÀNG
A2: 106 mã. Xếp theo nhóm → loại khí → thể tích tăng dần. Dung dịch chuẩn tách riêng: DD-PH, DD-AMONI, DD-COD, DD-TSS.
A4: MÃ HÀNG | B4: ANH SỬA | C4: Nhóm | D4: Loại khí / Vật liệu | E4: Thể tích | F4: ĐVT | G4: Tên đầy đủ (tham chiếu)
A5: DD-PH | C5: Dung dịch chuẩn | D5: pH | E5: 500ml | F5: Chai | G5: Dung dịch chuẩn PH7 | Dung dịch chuẩn pH | Dung dịch chuẩn pH 10 | Dung dịch chuẩn pH 4 | Dung dịch chuẩn pH 7
A6: DD-AMONI | C6: Dung dịch chuẩn | D6: Amoni (NH4-N) | E6: 500ml | F6: Chai | G6: Dung dich chuẩn Amoni | Dung dịch chuẩn NH4 | Dung dịch chuẩn NH4-N | Dung dịch chuẩn NH4-N 100ppm | Dung dịch chuẩn NH4-N 10ppm | Dung dịch chuẩn NH4-N 50ppm | Dung dịch chuẩn NH4-N 5ppm
A7: DD-COD | C7: Dung dịch chuẩn | D7: COD | E7: 500ml | F7: Chai | G7: Dung dịch chuẩn COD | Dung dịch chuẩn COD 100ppm | Dung dịch chuẩn COD 10ppm | Dung dịch chuẩn COD 300ppm | Dung dịch chuẩn COD 50ppm
A8: DD-TSS | C8: Dung dịch chuẩn | D8: TSS | E8: 500ml | F8: Chai | G8: Dung dịch chuẩn TSS | Dung dịch chuẩn TSS 100ppm | Dung dịch chuẩn TSS 10ppm | Dung dịch chuẩn TSS 50ppm
A9: DD-KHAC | C9: Dung dịch chuẩn | D9: Khác (NO3...) | F9: Chai | G9: Dung dịch chuẩn NO3
A10: KC-KHAC | C10: Khí chuẩn | F10: Bình | G10: Đầu chuyển đổi
A11: KC-ACETONE-40L | C11: Khí chuẩn | D11: ACETONE | E11: 40L | F11: Bình | G11: Khí chuẩn Acetone (C3H6O)
A12: KC-BENZEN-8L | C12: Khí chuẩn | D12: BENZEN | E12: 8L | F12: Bình | G12: Khí chuẩn Benzen
A13: KC-C3H6-8L | C13: Khí chuẩn | D13: C3H6 | E13: 8L | F13: Bình | G13: Khí chuẩn C3H6
A14: KC-CH4 | C14: Khí chuẩn | D14: CH4 | F14: Bình | G14: Hỗn hợp khí chuẩn CH4/N2
A15: KC-CH4-8L | C15: Khí chuẩn | D15: CH4 | E15: 8L | F15: Bình | G15: Bình khí CH4
A16: KC-CHU-10L | C16: Khí chuẩn | D16: CHU | E16: 10L | F16: Bình | G16: Bình khí chuẩn
A17: KC-CO | C17: Khí chuẩn | D17: CO | F17: Bình | G17: Khí chuẩn CO
A18: KC-CO-1L | C18: Khí chuẩn | D18: CO | E18: 1L | F18: Bình | G18: Khí chuẩn CO
A19: KC-CO-1.2L | C19: Khí chuẩn | D19: CO | E19: 1.2L | F19: Bình | G19: Khí chuẩn CO
A20: KC-CO-8L | C20: Khí chuẩn | D20: CO | E20: 8L | F20: Bình | G20: Bình Khí CO | Bình khí CO | Bình khí chuẩn CO | Bình khí hiệu chuẩn CO | CO calibration gas | Khí CO | Khí chuẩn CO
A21: KC-CO-10L | C21: Khí chuẩn | D21: CO | E21: 10L | F21: Bình | G21: Bình khí CO | Khí chuẩn CO
A22: KC-CO-20L | C22: Khí chuẩn | D22: CO | E22: 20L | F22: Bình | G22: Bình khí hiệu chuẩn CO | Khí chuẩn CO
A23: KC-CO-40L | C23: Khí chuẩn | D23: CO | E23: 40L | F23: Bình | G23: CO calibration gas | Khí chuẩn CO
A24: KC-CO-50L | C24: Khí chuẩn | D24: CO | E24: 50L | F24: Bình | G24: Bình khí hiệu chuẩn CO
A25: KC-CO2 | C25: Khí chuẩn | D25: CO2 | F25: Bình | G25: Khí chuẩn CO2
A26: KC-CO2-1L | C26: Khí chuẩn | D26: CO2 | E26: 1L | F26: Bình | G26: Khí chuẩn CO2 | Khí chuẩn hỗn hợp CO/CO2/NO
A27: KC-CO2-8L | C27: Khí chuẩn | D27: CO2 | E27: 8L | F27: Bình | G27: Bình khí chuẩn CO2 | Khí CO2/O2 | Khí chuẩn CO2
A28: KC-CO2-10L | C28: Khí chuẩn | D28: CO2 | E28: 10L | F28: Bình | G28: Bình khí CO2
A29: KC-CO2-40L | C29: Khí chuẩn | D29: CO2 | E29: 40L | F29: Bình | G29: CO2 calibration gas | Khí chuẩn CO2 | Khí chuẩn hỗn hợp CO/CO2/NO/SO2
A30: KC-ETHANOL-40L | C30: Khí chuẩn | D30: ETHANOL | E30: 40L | F30: Bình | G30: Khí chuẩn Ethanol (C2H6O)
A31: KC-H2-10L | C31: Khí chuẩn | D31: H2 | E31: 10L | F31: Bình | G31: Khí chuẩn H2
A32: KC-H2S | C32: Khí chuẩn | D32: H2S | F32: Bình | G32: Hỗn hợp khí chuẩn CH4/O2/CO/H2S | Khí chuẩn H2S | Khí chuẩn hỗn hợp CH4/O2/CO/H2S
A33: KC-H2S-10L | C33: Khí chuẩn | D33: H2S | E33: 10L | F33: Bình | G33: Khí chuẩn H2S
A34: KC-HCL-8L | C34: Khí chuẩn | D34: HCL | E34: 8L | F34: Bình | G34: Bình Khí HCL | Bình khí HCL | Bình khí chuẩn HCL | Bình khí hiệu chuẩn HCL | HCL calibration gas | Khí HCL | Khí chuẩn HCL | Khí chuẩn HCl
A35: KC-HCL-10L | C35: Khí chuẩn | D35: HCL | E35: 10L | F35: Bình | G35: Bình HCL | Bình khí HCL | Bình khí chuẩn hỗn hợp HCl | Khí chuẩn HCL | Khí chuẩn HCl
A36: KC-HCL-40L | C36: Khí chuẩn | D36: HCL | E36: 40L | F36: Bình | G36: Bình khí HCl | Khí chuẩn HCL
A37: KC-HF-8L | C37: Khí chuẩn | D37: HF | E37: 8L | F37: Bình | G37: Bình HF | Bình Khi HF | Bình khí HF | Bình khí chuẩn HF | Khí chuẩn HF
A38: KC-HF-10L | C38: Khí chuẩn | D38: HF | E38: 10L | F38: Bình | G38: Khí chuẩn HF
A39: KC-HF-30L | C39: Khí chuẩn | D39: HF | E39: 30L | F39: Bình | G39: Khí chuẩn HF
A40: KC-HI-8L | C40: Khí chuẩn | D40: HI | E40: 8L | F40: Bình | G40: Khí hiệu chuẩn đa chỉ tiêu
A41: KC-N2 | C41: Khí chuẩn | D41: N2 | F41: Bình | G41: Bình khí N2 | Khí chuẩn N2
...

Sheet DM. Hợp đồng bán
A1: DANH MỤC HỢP ĐỒNG BÁN
A2: 130 hợp đồng.
A4: MÃ HỢP ĐỒNG
A5: 876/2025/HĐSXKD-CP
A6: 2025/2609/OMV - DEAHAN
A7: 251022/HĐKT/OMV-CNCT
A8: 251028/HĐKT/OMV-KNK
A9: 251118/HĐKT/OMV-MTTĐ
A10: 251118/HĐKT/OMV-MTLA
A11: 11-18/2/2025/HĐ-KHĐT
A12: 251203/HĐKT/OMV-HGQ
A13: 251209/HĐKT/OMV-SESE
... A134: 260821/HĐKT/OMV-TTĐ

Sheet 1. NhapKho
A1: NHẬP KHO — mỗi dòng hóa đơn là một LÔ
A2: 47 lô từ 2 hóa đơn Phú Tài Miền Nam. Mã lô ở cột C là khóa để trừ kho.
A4: Ngày | B4: Số hóa đơn | C4: MÃ LÔ | D4: Nhà cung cấp | E4: Dòng HĐ | F4: MÃ HÀNG | G4: Quy cách / nồng độ theo hóa đơn | H4: SL nhập | I4: Đơn giá chưa VAT | J4: Thành tiền | K4: VAT % | L4: Ghi chú
A5: 46193 | B5: HĐ 259 | C5: L259-01 | D5: Phú Tài Miền Nam | E5: 1 | F5: KC-O2-10L | G5: Khí chuẩn Oxi (=<23%), cân bằng Nitơ (>77%), thể tích 10 lít - bình nhôm, mới 100%. | H5: 4 | I5: 6000000 | J5: =H5*I5 -> 24000000 | K5: 0.08
A6: 46193 | B6: HĐ 259 | C6: L259-02 | D6: Phú Tài Miền Nam | E6: 2 | F6: KC-HF-30L | G6: Khí chuẩn Hydrogen fluoride (0.0001-0.01 %) , cân bằng Nitơ (99.99-99.9999 %), thể tích 30 lít - bình nhôm, mới 100%. | H6: 1 | I6: 22000000 | J6: =H6*I6 -> 22000000 | K6: 0.08
A7: 46193 | B7: HĐ 259 | C7: L259-03 | D7: Phú Tài Miền Nam | E7: 3 | F7: KC-NH3-30L | G7: Khí chuẩn Amonia (0.00001%-0.9999%), cân bằng Nitơ (99.99-99.9999 %), thể tích 30 lít - bình nhôm, mới 100%. | H7: 1 | I7: 22000000 | J7: =H7*I7 -> 22000000 | K7: 0.08
A8: 46193 | B8: HĐ 259 | C8: L259-04 | D8: Phú Tài Miền Nam | E8: 4 | F8: KC-NH3-30L | G8: Khí chuẩn Amonia (0.00001%-0.9999%), cân bằng Nitơ (99.99-99.9999 %), thể tích 30 lít - bình nhôm, mới 100%. | H8: 1 | I8: 22000000 | J8: =H8*I8 -> 22000000 | K8: 0.08
A9: 46193 | B9: HĐ 259 | C9: L259-05 | D9: Phú Tài Miền Nam | E9: 5 | F9: KC-O2-8L | G9: Khí chuẩn Oxi (=<23%), cân bằng Nitơ (> 77%), thể tích 8 lít - bình nhôm, mới 100% | H9: 12 | I9: 5000000 | J9: =H9*I9 -> 60000000 | K9: 0.08
A10: 46193 | B10: HĐ 259 | C10: L259-06 | D10: Phú Tài Miền Nam | E10: 6 | F10: KC-SO2NOCO-8L | G10: Khí Sulfur dioxide (0.00001-0.6%), Nitric oxide (0.00001-0.21%), Carbon monoxide (0.0001- 0.9999%), Nitrogen(98.1901-99.9998%), thể tích 8lít - bình nhôm, mới 100%. | H10: 11 | I10: 7000000 | J10: =H10*I10 -> 77000000 | K10: 0.08
A11: 46193 | B11: HĐ 259 | C11: L259-07 | D11: Phú Tài Miền Nam | E11: 7 | F11: KC-NO2-10L | G11: Khí chuẩn Nitrogen dioxide (0.01%), cân bằng Nitrogen(99.99%), thể tích 10 lít - bình nhôm,mới 100%. | H11: 2 | I11: 9000000 | J11: =H11*I11 -> 18000000 | K11: 0.08
A12: 46193 | B12: HĐ 259 | C12: L259-08 | D12: Phú Tài Miền Nam | E12: 8 | F12: KC-H2S-10L | G12: Khí chuẩn Hidrogen Sulfide (0.00001%-0.9999%), cân bằng Nitrogen (99.99-99.9999 %), thể tích 10 lít - bình nhôm, mới 100% | H12: 2 | I12: 10000000 | J12: =H12*I12 -> 20000000 | K12: 0.08
A13: 46193 | B13: HĐ 259 | C13: L259-09 | D13: Phú Tài Miền Nam | E13: 9 | F13: KC-SO2-10L | G13: Khí chuẩn hỗn hợp Sulfur dioxide (0.00001-0.6%), cân bằng Nitrogen (99.99999-99.4 %), thể tích 10 lít - bình nhôm, mới 100% | H13: 2 | I13: 7000000 | J13: =H13*I13 -> 14000000 | K13: 0.08
A14: 46193 | B14: HĐ 259 | C14: L259-10 | D14: Phú Tài Miền Nam | E14: 10 | F14: KC-CO-20L | G14: Khí chuẩn hỗn hợp Carbon monoxide (0.0001- 0.9999%), cân bằng Nitrogen (99,9999-99,0001%), thể tích 20 lít - bình nhôm, mới 100% | H14: 1 | I14: 12000000 | J14: =H14*I14 -> 12000000 | K14: 0.08
A15: 46193 | B15: HĐ 259 | C15: L259-11 | D15: Phú Tài Miền Nam | E15: 11 | F15: KC-NO-20L | G15: Khí chuẩn hỗn hợp Nitric oxide (0.00001-0.21%), cân bằng Nitrogen (98.1901-99.9998%), thể tích 20 lít - bình nhôm, mới 100% | H15: 1 | I15: 12000000 | J15: =H15*I15 -> 12000000 | K15: 0.08
A16: 46193 | B16: HĐ 259 | C16: L259-12 | D16: Phú Tài Miền Nam | E16: 12 | F16: KC-SO2-20L | G16: Khí chuẩn hỗn hợp Sulfur dioxide (0.00001-0.6%), cân bằng Nitrogen (99.99999-99.4 %), thể tích 20 lít - bình nhôm, mới 100% | H16: 1 | I16: 12000000 | J16: =H16*I16 -> 12000000 | K16: 0.08
... A51: 46196 | B51: HĐ 262 | C51: L262-28 | D51: Phú Tài Miền Nam | E51: 28 | F51: VO-NHOM-50L | G51: Bình chứa khí nén bằng nhôm (bình rỗng), dung tích 50 lít, mới 100% | H51: 4 | I51: 12500000 | J51: =H51*I51 -> 50000000 | K51: 0.08
J52: =IF(OR(H52="",I52=""),"",H52*I52)
J53: =IF(OR(H53="",I53=""),"",H53*I53)
J54: =IF(OR(H54="",I54=""),"",H54*I54)
J55: =IF(OR(H55="",I55=""),"",H55*I55)
J56: =IF(OR(H56="",I56=""),"",H56*I56)
J57: =IF(OR(H57="",I57=""),"",H57*I57)
J58: =IF(OR(H58="",I58=""),"",H58*I58)
J59: =IF(OR(H59="",I59=""),"",H59*I59)
J60: =IF(OR(H60="",I60=""),"",H60*I60)
J61: =IF(OR(H61="",I61=""),"",H61*I61)
J62: =IF(OR(H62="",I62=""),"",H62*I62)
J63: =IF(OR(H63="",I63=""),"",H63*I63)
... J351: =IF(OR(H351="",I351=""),"",H351*I351)
G353: CỘNG | H353: =SUM(H5:H351) -> 120 | J353: =SUM(J5:J351) -> 965800000

Sheet 2. XuatKho
A1: XUẤT KHO — trừ kho và chia cho hợp đồng
A2: Mỗi lần xuất một dòng. Chọn MÃ LÔ và MÃ HỢP ĐỒNG từ dropdown, điền số lượng. Giá vốn tự lấy theo lô.
A4: Ngày xuất | B4: Số phiếu xuất | C4: MÃ LÔ | D4: MÃ HỢP ĐỒNG BÁN | E4: Tên hàng ghi trên hợp đồng (nhập tay) | F4: SL xuất | G4: Đơn giá vốn (tự lấy theo lô) | H4: Quy cách của lô | I4: GIÁ VỐN XUẤT | J4: Mã hàng | K4: Ghi chú
G5: =IFERROR(INDEX('1. NhapKho'!$I$5:$I$351,MATCH($C5,'1. NhapKho'!$C$5:$C$351,0)),"") | H5: =IFERROR(INDEX('1. NhapKho'!$G$5:$G$351,MATCH($C5,'1. NhapKho'!$C$5:$C$351,0)),"") | I5: =IF(OR($C5="",$F5=""),"",$F5*$G5) | J5: =IFERROR(INDEX('1. NhapKho'!$F$5:$F$351,MATCH($C5,'1. NhapKho'!$C$5:$C$351,0)),"")
G6: =IFERROR(INDEX('1. NhapKho'!$I$5:$I$351,MATCH($C6,'1. NhapKho'!$C$5:$C$351,0)),"") | H6: =IFERROR(INDEX('1. NhapKho'!$G$5:$G$351,MATCH($C6,'1. NhapKho'!$C$5:$C$351,0)),"") | I6: =IF(OR($C6="",$F6=""),"",$F6*$G6) | J6: =IFERROR(INDEX('1. NhapKho'!$F$5:$F$351,MATCH($C6,'1. NhapKho'!$C$5:$C$351,0)),"")
G7: =IFERROR(INDEX('1. NhapKho'!$I$5:$I$351,MATCH($C7,'1. NhapKho'!$C$5:$C$351,0)),"") | H7: =IFERROR(INDEX('1. NhapKho'!$G$5:$G$351,MATCH($C7,'1. NhapKho'!$C$5:$C$351,0)),"") | I7: =IF(OR($C7="",$F7=""),"",$F7*$G7) | J7: =IFERROR(INDEX('1. NhapKho'!$F$5:$F$351,MATCH($C7,'1. NhapKho'!$C$5:$C$351,0)),"")
G8: =IFERROR(INDEX('1. NhapKho'!$I$5:$I$351,MATCH($C8,'1. NhapKho'!$C$5:$C$351,0)),"") | H8: =IFERROR(INDEX('1. NhapKho'!$G$5:$G$351,MATCH($C8,'1. NhapKho'!$C$5:$C$351,0)),"") | I8: =IF(OR($C8="",$F8=""),"",$F8*$G8) | J8: =IFERROR(INDEX('1. NhapKho'!$F$5:$F$351,MATCH($C8,'1. NhapKho'!$C$5:$C$351,0)),"")
G9: =IFERROR(INDEX('1. NhapKho'!$I$5:$I$351,MATCH($C9,'1. NhapKho'!$C$5:$C$351,0)),"") | H9: =IFERROR(INDEX('1. NhapKho'!$G$5:$G$351,MATCH($C9,'1. NhapKho'!$C$5:$C$351,0)),"") | I9: =IF(OR($C9="",$F9=""),"",$F9*$G9) | J9: =IFERROR(INDEX('1. NhapKho'!$F$5:$F$351,MATCH($C9,'1. NhapKho'!$C$5:$C$351,0)),"")
G10: =IFERROR(INDEX('1. NhapKho'!$I$5:$I$351,MATCH($C10,'1. NhapKho'!$C$5:$C$351,0)),"") | H10: =IFERROR(INDEX('1. NhapKho'!$G$5:$G$351,MATCH($C10,'1. NhapKho'!$C$5:$C$351,0)),"") | I10: =IF(OR($C10="",$F10=""),"",$F10*$G10) | J10: =IFERROR(INDEX('1. NhapKho'!$F$5:$F$351,MATCH($C10,'1. NhapKho'!$C$5:$C$351,0)),"")
G11: =IFERROR(INDEX('1. NhapKho'!$I$5:$I$351,MATCH($C11,'1. NhapKho'!$C$5:$C$351,0)),"") | H11: =IFERROR(INDEX('1. NhapKho'!$G$5:$G$351,MATCH($C11,'1. NhapKho'!$C$5:$C$351,0)),"") | I11: =IF(OR($C11="",$F11=""),"",$F11*$G11) | J11: =IFERROR(INDEX('1. NhapKho'!$F$5:$F$351,MATCH($C11,'1. NhapKho'!$C$5:$C$351,0)),"")
G12: =IFERROR(INDEX('1. NhapKho'!$I$5:$I$351,MATCH($C12,'1. NhapKho'!$C$5:$C$351,0)),"") | H12: =IFERROR(INDEX('1. NhapKho'!$G$5:$G$351,MATCH($C12,'1. NhapKho'!$C$5:$C$351,0)),"") | I12: =IF(OR($C12="",$F12=""),"",$F12*$G12) | J12: =IFERROR(INDEX('1. NhapKho'!$F$5:$F$351,MATCH($C12,'1. NhapKho'!$C$5:$C$351,0)),"")
G13: =IFERROR(INDEX('1. NhapKho'!$I$5:$I$351,MATCH($C13,'1. NhapKho'!$C$5:$C$351,0)),"") | H13: =IFERROR(INDEX('1. NhapKho'!$G$5:$G$351,MATCH($C13,'1. NhapKho'!$C$5:$C$351,0)),"") | I13: =IF(OR($C13="",$F13=""),"",$F13*$G13) | J13: =IFERROR(INDEX('1. NhapKho'!$F$5:$F$351,MATCH($C13,'1. NhapKho'!$C$5:$C$351,0)),"")
G14: =IFERROR(INDEX('1. NhapKho'!$I$5:$I$351,MATCH($C14,'1. NhapKho'!$C$5:$C$351,0)),"") | H14: =IFERROR(INDEX('1. NhapKho'!$G$5:$G$351,MATCH($C14,'1. NhapKho'!$C$5:$C$351,0)),"") | I14: =IF(OR($C14="",$F14=""),"",$F14*$G14) | J14: =IFERROR(INDEX('1. NhapKho'!$F$5:$F$351,MATCH($C14,'1. NhapKho'!$C$5:$C$351,0)),"")
G15: =IFERROR(INDEX('1. NhapKho'!$I$5:$I$351,MATCH($C15,'1. NhapKho'!$C$5:$C$351,0)),"") | H15: =IFERROR(INDEX('1. NhapKho'!$G$5:$G$351,MATCH($C15,'1. NhapKho'!$C$5:$C$351,0)),"") | I15: =IF(OR($C15="",$F15=""),"",$F15*$G15) | J15: =IFERROR(INDEX('1. NhapKho'!$F$5:$F$351,MATCH($C15,'1. NhapKho'!$C$5:$C$351,0)),"")
G16: =IFERROR(INDEX('1. NhapKho'!$I$5:$I$351,MATCH($C16,'1. NhapKho'!$C$5:$C$351,0)),"") | H16: =IFERROR(INDEX('1. NhapKho'!$G$5:$G$351,MATCH($C16,'1. NhapKho'!$C$5:$C$351,0)),"") | I16: =IF(OR($C16="",$F16=""),"",$F16*$G16) | J16: =IFERROR(INDEX('1. NhapKho'!$F$5:$F$351,MATCH($C16,'1. NhapKho'!$C$5:$C$351,0)),"")
... G254: =IFERROR(INDEX('1. NhapKho'!$I$5:$I$351,MATCH($C254,'1. NhapKho'!$C$5:$C$351,0)),"") | H254: =IFERROR(INDEX('1. NhapKho'!$G$5:$G$351,MATCH($C254,'1. NhapKho'!$C$5:$C$351,0)),"") | I254: =IF(OR($C254="",$F254=""),"",$F254*$G254) | J254: =IFERROR(INDEX('1. NhapKho'!$F$5:$F$351,MATCH($C254,'1. NhapKho'!$C$5:$C$351,0)),"")
E256: CỘNG | F256: =SUM(F5:F254) -> 0 | I256: =SUM(I5:I254) -> 0

Sheet 3. TonTheoLo
A1: TỒN KHO THEO LÔ
A2: Nhập − Xuất = Tồn. Cột cảnh báo báo đỏ nếu xuất quá số nhập.
A4: MÃ LÔ | B4: Ngày nhập | C4: Số hóa đơn | D4: MÃ HÀNG | E4: Quy cách / nồng độ | F4: SL nhập | G4: SL đã xuất | H4: TỒN | I4: Đơn giá vốn | J4: GIÁ TRỊ TỒN | K4: Cảnh báo
A5: L259-01 | B5: 46193 | C5: HĐ 259 | D5: KC-O2-10L | E5: Khí chuẩn Oxi (=<23%), cân bằng Nitơ (>77%), thể tích 10 lít - bình nhôm, mới 100%. | F5: =IFERROR(INDEX('1. NhapKho'!$H$5:$H$351,MATCH($A5,'1. NhapKho'!$C$5:$C$351,0)),0) -> 4 | G5: =SUMIFS('2. XuatKho'!$F$5:$F$254,'2. XuatKho'!$C$5:$C$254,$A5) -> 0 | H5: =F5-G5 -> 4 | I5: =IFERROR(INDEX('1. NhapKho'!$I$5:$I$351,MATCH($A5,'1. NhapKho'!$C$5:$C$351,0)),0) -> 6000000 | J5: =H5*I5 -> 24000000 | K5: =IF(H5<0,"XUẤT QUÁ TỒN "&-H5&" bình","")
A6: L259-02 | B6: 46193 | C6: HĐ 259 | D6: KC-HF-30L | E6: Khí chuẩn Hydrogen fluoride (0.0001-0.01 %) , cân bằng Nitơ (99.99-99.9999 %), thể tích 30 lít - bình nhôm, mới 100%. | F6: =IFERROR(INDEX('1. NhapKho'!$H$5:$H$351,MATCH($A6,'1. NhapKho'!$C$5:$C$351,0)),0) -> 1 | G6: =SUMIFS('2. XuatKho'!$F$5:$F$254,'2. XuatKho'!$C$5:$C$254,$A6) -> 0 | H6: =F6-G6 -> 1 | I6: =IFERROR(INDEX('1. NhapKho'!$I$5:$I$351,MATCH($A6,'1. NhapKho'!$C$5:$C$351,0)),0) -> 22000000 | J6: =H6*I6 -> 22000000 | K6: =IF(H6<0,"XUẤT QUÁ TỒN "&-H6&" bình","")
A7: L259-03 | B7: 46193 | C7: HĐ 259 | D7: KC-NH3-30L | E7: Khí chuẩn Amonia (0.00001%-0.9999%), cân bằng Nitơ (99.99-99.9999 %), thể tích 30 lít - bình nhôm, mới 100%. | F7: =IFERROR(INDEX('1. NhapKho'!$H$5:$H$351,MATCH($A7,'1. NhapKho'!$C$5:$C$351,0)),0) -> 1 | G7: =SUMIFS('2. XuatKho'!$F$5:$F$254,'2. XuatKho'!$C$5:$C$254,$A7) -> 0 | H7: =F7-G7 -> 1 | I7: =IFERROR(INDEX('1. NhapKho'!$I$5:$I$351,MATCH($A7,'1. NhapKho'!$C$5:$C$351,0)),0) -> 22000000 | J7: =H7*I7 -> 22000000 | K7: =IF(H7<0,"XUẤT QUÁ TỒN "&-H7&" bình","")
A8: L259-04 | B8: 46193 | C8: HĐ 259 | D8: KC-NH3-30L | E8: Khí chuẩn Amonia (0.00001%-0.9999%), cân bằng Nitơ (99.99-99.9999 %), thể tích 30 lít - bình nhôm, mới 100%. | F8: =IFERROR(INDEX('1. NhapKho'!$H$5:$H$351,MATCH($A8,'1. NhapKho'!$C$5:$C$351,0)),0) -> 1 | G8: =SUMIFS('2. XuatKho'!$F$5:$F$254,'2. XuatKho'!$C$5:$C$254,$A8) -> 0 | H8: =F8-G8 -> 1 | I8: =IFERROR(INDEX('1. NhapKho'!$I$5:$I$351,MATCH($A8,'1. NhapKho'!$C$5:$C$351,0)),0) -> 22000000 | J8: =H8*I8 -> 22000000 | K8: =IF(H8<0,"XUẤT QUÁ TỒN "&-H8&" bình","")
A9: L259-05 | B9: 46193 | C9: HĐ 259 | D9: KC-O2-8L | E9: Khí chuẩn Oxi (=<23%), cân bằng Nitơ (> 77%), thể tích 8 lít - bình nhôm, mới 100% | F9: =IFERROR(INDEX('1. NhapKho'!$H$5:$H$351,MATCH($A9,'1. NhapKho'!$C$5:$C$351,0)),0) -> 12 | G9: =SUMIFS('2. XuatKho'!$F$5:$F$254,'2. XuatKho'!$C$5:$C$254,$A9) -> 0 | H9: =F9-G9 -> 12 | I9: =IFERROR(INDEX('1. NhapKho'!$I$5:$I$351,MATCH($A9,'1. NhapKho'!$C$5:$C$351,0)),0) -> 5000000 | J9: =H9*I9 -> 60000000 | K9: =IF(H9<0,"XUẤT QUÁ TỒN "&-H9&" bình","")
A10: L259-06 | B10: 46193 | C10: HĐ 259 | D10: KC-SO2NOCO-8L | E10: Khí Sulfur dioxide (0.00001-0.6%), Nitric oxide (0.00001-0.21%), Carbon monoxide (0.0001- 0.9999%), Nitrogen(98.1901-99.9998%), thể tích 8lít - bình nhôm, mới 100%. | F10: =IFERROR(INDEX('1. NhapKho'!$H$5:$H$351,MATCH($A10,'1. NhapKho'!$C$5:$C$351,0)),0) -> 11 | G10: =SUMIFS('2. XuatKho'!$F$5:$F$254,'2. XuatKho'!$C$5:$C$254,$A10) -> 0 | H10: =F10-G10 -> 11 | I10: =IFERROR(INDEX('1. NhapKho'!$I$5:$I$351,MATCH($A10,'1. NhapKho'!$C$5:$C$351,0)),0) -> 7000000 | J10: =H10*I10 -> 77000000 | K10: =IF(H10<0,"XUẤT QUÁ TỒN "&-H10&" bình","")
A11: L259-07 | B11: 46193 | C11: HĐ 259 | D11: KC-NO2-10L | E11: Khí chuẩn Nitrogen dioxide (0.01%), cân bằng Nitrogen(99.99%), thể tích 10 lít - bình nhôm,mới 100%. | F11: =IFERROR(INDEX('1. NhapKho'!$H$5:$H$351,MATCH($A11,'1. NhapKho'!$C$5:$C$351,0)),0) -> 2 | G11: =SUMIFS('2. XuatKho'!$F$5:$F$254,'2. XuatKho'!$C$5:$C$254,$A11) -> 0 | H11: =F11-G11 -> 2 | I11: =IFERROR(INDEX('1. NhapKho'!$I$5:$I$351,MATCH($A11,'1. NhapKho'!$C$5:$C$351,0)),0) -> 9000000 | J11: =H11*I11 -> 18000000 | K11: =IF(H11<0,"XUẤT QUÁ TỒN "&-H11&" bình","")
A12: L259-08 | B12: 46193 | C12: HĐ 259 | D12: KC-H2S-10L | E12: Khí chuẩn Hidrogen Sulfide (0.00001%-0.9999%), cân bằng Nitrogen (99.99-99.9999 %), thể tích 10 lít - bình nhôm, mới 100% | F12: =IFERROR(INDEX('1. NhapKho'!$H$5:$H$351,MATCH($A12,'1. NhapKho'!$C$5:$C$351,0)),0) -> 2 | G12: =SUMIFS('2. XuatKho'!$F$5:$F$254,'2. XuatKho'!$C$5:$C$254,$A12) -> 0 | H12: =F12-G12 -> 2 | I12: =IFERROR(INDEX('1. NhapKho'!$I$5:$I$351,MATCH($A12,'1. NhapKho'!$C$5:$C$351,0)),0) -> 10000000 | J12: =H12*I12 -> 20000000 | K12: =IF(H12<0,"XUẤT QUÁ TỒN "&-H12&" bình","")
A13: L259-09 | B13: 46193 | C13: HĐ 259 | D13: KC-SO2-10L | E13: Khí chuẩn hỗn hợp Sulfur dioxide (0.00001-0.6%), cân bằng Nitrogen (99.99999-99.4 %), thể tích 10 lít - bình nhôm, mới 100% | F13: =IFERROR(INDEX('1. NhapKho'!$H$5:$H$351,MATCH($A13,'1. NhapKho'!$C$5:$C$351,0)),0) -> 2 | G13: =SUMIFS('2. XuatKho'!$F$5:$F$254,'2. XuatKho'!$C$5:$C$254,$A13) -> 0 | H13: =F13-G13 -> 2 | I13: =IFERROR(INDEX('1. NhapKho'!$I$5:$I$351,MATCH($A13,'1. NhapKho'!$C$5:$C$351,0)),0) -> 7000000 | J13: =H13*I13 -> 14000000 | K13: =IF(H13<0,"XUẤT QUÁ TỒN "&-H13&" bình","")
A14: L259-10 | B14: 46193 | C14: HĐ 259 | D14: KC-CO-20L | E14: Khí chuẩn hỗn hợp Carbon monoxide (0.0001- 0.9999%), cân bằng Nitrogen (99,9999-99,0001%), thể tích 20 lít - bình nhôm, mới 100% | F14: =IFERROR(INDEX('1. NhapKho'!$H$5:$H$351,MATCH($A14,'1. NhapKho'!$C$5:$C$351,0)),0) -> 1 | G14: =SUMIFS('2. XuatKho'!$F$5:$F$254,'2. XuatKho'!$C$5:$C$254,$A14) -> 0 | H14: =F14-G14 -> 1 | I14: =IFERROR(INDEX('1. NhapKho'!$I$5:$I$351,MATCH($A14,'1. NhapKho'!$C$5:$C$351,0)),0) -> 12000000 | J14: =H14*I14 -> 12000000 | K14: =IF(H14<0,"XUẤT QUÁ TỒN "&-H14&" bình","")
A15: L259-11 | B15: 46193 | C15: HĐ 259 | D15: KC-NO-20L | E15: Khí chuẩn hỗn hợp Nitric oxide (0.00001-0.21%), cân bằng Nitrogen (98.1901-99.9998%), thể tích 20 lít - bình nhôm, mới 100% | F15: =IFERROR(INDEX('1. NhapKho'!$H$5:$H$351,MATCH($A15,'1. NhapKho'!$C$5:$C$351,0)),0) -> 1 | G15: =SUMIFS('2. XuatKho'!$F$5:$F$254,'2. XuatKho'!$C$5:$C$254,$A15) -> 0 | H15: =F15-G15 -> 1 | I15: =IFERROR(INDEX('1. NhapKho'!$I$5:$I$351,MATCH($A15,'1. NhapKho'!$C$5:$C$351,0)),0) -> 12000000 | J15: =H15*I15 -> 12000000 | K15: =IF(H15<0,"XUẤT QUÁ TỒN "&-H15&" bình","")
A16: L259-12 | B16: 46193 | C16: HĐ 259 | D16: KC-SO2-20L | E16: Khí chuẩn hỗn hợp Sulfur dioxide (0.00001-0.6%), cân bằng Nitrogen (99.99999-99.4 %), thể tích 20 lít - bình nhôm, mới 100% | F16: =IFERROR(INDEX('1. NhapKho'!$H$5:$H$351,MATCH($A16,'1. NhapKho'!$C$5:$C$351,0)),0) -> 1 | G16: =SUMIFS('2. XuatKho'!$F$5:$F$254,'2. XuatKho'!$C$5:$C$254,$A16) -> 0 | H16: =F16-G16 -> 1 | I16: =IFERROR(INDEX('1. NhapKho'!$I$5:$I$351,MATCH($A16,'1. NhapKho'!$C$5:$C$351,0)),0) -> 12000000 | J16: =H16*I16 -> 12000000 | K16: =IF(H16<0,"XUẤT QUÁ TỒN "&-H16&" bình","")
... A51: L262-28 | B51: 46196 | C51: HĐ 262 | D51: VO-NHOM-50L | E51: Bình chứa khí nén bằng nhôm (bình rỗng), dung tích 50 lít, mới 100% | F51: =IFERROR(INDEX('1. NhapKho'!$H$5:$H$351,MATCH($A51,'1. NhapKho'!$C$5:$C$351,0)),0) -> 4 | G51: =SUMIFS('2. XuatKho'!$F$5:$F$254,'2. XuatKho'!$C$5:$C$254,$A51) -> 0 | H51: =F51-G51 -> 4 | I51: =IFERROR(INDEX('1. NhapKho'!$I$5:$I$351,MATCH($A51,'1. NhapKho'!$C$5:$C$351,0)),0) -> 12500000 | J51: =H51*I51 -> 50000000 | K51: =IF(H51<0,"XUẤT QUÁ TỒN "&-H51&" bình","")
E53: CỘNG | F53: =SUM(F5:F51) -> 120 | G53: =SUM(G5:G51) -> 0 | H53: =SUM(H5:H51) -> 120 | J53: =SUM(J5:J51) -> 965800000

Sheet 3b. TonTheoMaHang
A1: TỒN KHO GỘP THEO MÃ HÀNG
A2: So với kiểm kê thực tế 19/08/2026. Cùng thứ tự với sheet DM. Mã hàng.
A4: MÃ HÀNG | B4: Nhóm | C4: Thể tích | D4: SL nhập | E4: SL đã xuất | F4: TỒN | G4: GIÁ TRỊ TỒN | H4: Kiểm kê 19/08 | I4: Lệch
A5: DD-PH | B5: Dung dịch chuẩn | C5: 500ml | D5: =SUMIFS('3. TonTheoLo'!$F$5:$F$51,'3. TonTheoLo'!$D$5:$D$51,$A5) -> 0 | E5: =SUMIFS('3. TonTheoLo'!$G$5:$G$51,'3. TonTheoLo'!$D$5:$D$51,$A5) -> 0 | F5: =SUMIFS('3. TonTheoLo'!$H$5:$H$51,'3. TonTheoLo'!$D$5:$D$51,$A5) -> 0 | G5: =SUMIFS('3. TonTheoLo'!$J$5:$J$51,'3. TonTheoLo'!$D$5:$D$51,$A5) -> 0 | H5: 0 | I5: =F5-H5 -> 0
A6: DD-AMONI | B6: Dung dịch chuẩn | C6: 500ml | D6: =SUMIFS('3. TonTheoLo'!$F$5:$F$51,'3. TonTheoLo'!$D$5:$D$51,$A6) -> 0 | E6: =SUMIFS('3. TonTheoLo'!$G$5:$G$51,'3. TonTheoLo'!$D$5:$D$51,$A6) -> 0 | F6: =SUMIFS('3. TonTheoLo'!$H$5:$H$51,'3. TonTheoLo'!$D$5:$D$51,$A6) -> 0 | G6: =SUMIFS('3. TonTheoLo'!$J$5:$J$51,'3. TonTheoLo'!$D$5:$D$51,$A6) -> 0 | H6: 0 | I6: =F6-H6 -> 0
A7: DD-COD | B7: Dung dịch chuẩn | C7: 500ml | D7: =SUMIFS('3. TonTheoLo'!$F$5:$F$51,'3. TonTheoLo'!$D$5:$D$51,$A7) -> 0 | E7: =SUMIFS('3. TonTheoLo'!$G$5:$G$51,'3. TonTheoLo'!$D$5:$D$51,$A7) -> 0 | F7: =SUMIFS('3. TonTheoLo'!$H$5:$H$51,'3. TonTheoLo'!$D$5:$D$51,$A7) -> 0 | G7: =SUMIFS('3. TonTheoLo'!$J$5:$J$51,'3. TonTheoLo'!$D$5:$D$51,$A7) -> 0 | H7: 0 | I7: =F7-H7 -> 0
A8: DD-TSS | B8: Dung dịch chuẩn | C8: 500ml | D8: =SUMIFS('3. TonTheoLo'!$F$5:$F$51,'3. TonTheoLo'!$D$5:$D$51,$A8) -> 0 | E8: =SUMIFS('3. TonTheoLo'!$G$5:$G$51,'3. TonTheoLo'!$D$5:$D$51,$A8) -> 0 | F8: =SUMIFS('3. TonTheoLo'!$H$5:$H$51,'3. TonTheoLo'!$D$5:$D$51,$A8) -> 0 | G8: =SUMIFS('3. TonTheoLo'!$J$5:$J$51,'3. TonTheoLo'!$D$5:$D$51,$A8) -> 0 | H8: 0 | I8: =F8-H8 -> 0
A9: DD-KHAC | B9: Dung dịch chuẩn | D9: =SUMIFS('3. TonTheoLo'!$F$5:$F$51,'3. TonTheoLo'!$D$5:$D$51,$A9) -> 0 | E9: =SUMIFS('3. TonTheoLo'!$G$5:$G$51,'3. TonTheoLo'!$D$5:$D$51,$A9) -> 0 | F9: =SUMIFS('3. TonTheoLo'!$H$5:$H$51,'3. TonTheoLo'!$D$5:$D$51,$A9) -> 0 | G9: =SUMIFS('3. TonTheoLo'!$J$5:$J$51,'3. TonTheoLo'!$D$5:$D$51,$A9) -> 0 | H9: 0 | I9: =F9-H9 -> 0
A10: KC-KHAC | B10: Khí chuẩn | D10: =SUMIFS('3. TonTheoLo'!$F$5:$F$51,'3. TonTheoLo'!$D$5:$D$51,$A10) -> 0 | E10: =SUMIFS('3. TonTheoLo'!$G$5:$G$51,'3. TonTheoLo'!$D$5:$D$51,$A10) -> 0 | F10: =SUMIFS('3. TonTheoLo'!$H$5:$H$51,'3. TonTheoLo'!$D$5:$D$51,$A10) -> 0 | G10: =SUMIFS('3. TonTheoLo'!$J$5:$J$51,'3. TonTheoLo'!$D$5:$D$51,$A10) -> 0 | H10: 0 | I10: =F10-H10 -> 0
A11: KC-ACETONE-40L | B11: Khí chuẩn | C11: 40L | D11: =SUMIFS('3. TonTheoLo'!$F$5:$F$51,'3. TonTheoLo'!$D$5:$D$51,$A11) -> 0 | E11: =SUMIFS('3. TonTheoLo'!$G$5:$G$51,'3. TonTheoLo'!$D$5:$D$51,$A11) -> 0 | F11: =SUMIFS('3. TonTheoLo'!$H$5:$H$51,'3. TonTheoLo'!$D$5:$D$51,$A11) -> 0 | G11: =SUMIFS('3. TonTheoLo'!$J$5:$J$51,'3. TonTheoLo'!$D$5:$D$51,$A11) -> 0 | H11: 0 | I11: =F11-H11 -> 0
A12: KC-BENZEN-8L | B12: Khí chuẩn | C12: 8L | D12: =SUMIFS('3. TonTheoLo'!$F$5:$F$51,'3. TonTheoLo'!$D$5:$D$51,$A12) -> 0 | E12: =SUMIFS('3. TonTheoLo'!$G$5:$G$51,'3. TonTheoLo'!$D$5:$D$51,$A12) -> 0 | F12: =SUMIFS('3. TonTheoLo'!$H$5:$H$51,'3. TonTheoLo'!$D$5:$D$51,$A12) -> 0 | G12: =SUMIFS('3. TonTheoLo'!$J$5:$J$51,'3. TonTheoLo'!$D$5:$D$51,$A12) -> 0 | H12: 0 | I12: =F12-H12 -> 0
A13: KC-C3H6-8L | B13: Khí chuẩn | C13: 8L | D13: =SUMIFS('3. TonTheoLo'!$F$5:$F$51,'3. TonTheoLo'!$D$5:$D$51,$A13) -> 0 | E13: =SUMIFS('3. TonTheoLo'!$G$5:$G$51,'3. TonTheoLo'!$D$5:$D$51,$A13) -> 0 | F13: =SUMIFS('3. TonTheoLo'!$H$5:$H$51,'3. TonTheoLo'!$D$5:$D$51,$A13) -> 0 | G13: =SUMIFS('3. TonTheoLo'!$J$5:$J$51,'3. TonTheoLo'!$D$5:$D$51,$A13) -> 0 | H13: 0 | I13: =F13-H13 -> 0
A14: KC-CH4 | B14: Khí chuẩn | D14: =SUMIFS('3. TonTheoLo'!$F$5:$F$51,'3. TonTheoLo'!$D$5:$D$51,$A14) -> 0 | E14: =SUMIFS('3. TonTheoLo'!$G$5:$G$51,'3. TonTheoLo'!$D$5:$D$51,$A14) -> 0 | F14: =SUMIFS('3. TonTheoLo'!$H$5:$H$51,'3. TonTheoLo'!$D$5:$D$51,$A14) -> 0 | G14: =SUMIFS('3. TonTheoLo'!$J$5:$J$51,'3. TonTheoLo'!$D$5:$D$51,$A14) -> 0 | H14: 0 | I14: =F14-H14 -> 0
A15: KC-CH4-8L | B15: Khí chuẩn | C15: 8L | D15: =SUMIFS('3. TonTheoLo'!$F$5:$F$51,'3. TonTheoLo'!$D$5:$D$51,$A15) -> 0 | E15: =SUMIFS('3. TonTheoLo'!$G$5:$G$51,'3. TonTheoLo'!$D$5:$D$51,$A15) -> 0 | F15: =SUMIFS('3. TonTheoLo'!$H$5:$H$51,'3. TonTheoLo'!$D$5:$D$51,$A15) -> 0 | G15: =SUMIFS('3. TonTheoLo'!$J$5:$J$51,'3. TonTheoLo'!$D$5:$D$51,$A15) -> 0 | H15: 0 | I15: =F15-H15 -> 0
A16: KC-CHU-10L | B16: Khí chuẩn | C16: 10L | D16: =SUMIFS('3. TonTheoLo'!$F$5:$F$51,'3. TonTheoLo'!$D$5:$D$51,$A16) -> 0 | E16: =SUMIFS('3. TonTheoLo'!$G$5:$G$51,'3. TonTheoLo'!$D$5:$D$51,$A16) -> 0 | F16: =SUMIFS('3. TonTheoLo'!$H$5:$H$51,'3. TonTheoLo'!$D$5:$D$51,$A16) -> 0 | G16: =SUMIFS('3. TonTheoLo'!$J$5:$J$51,'3. TonTheoLo'!$D$5:$D$51,$A16) -> 0 | H16: 0 | I16: =F16-H16 -> 0
A17: KC-CO | B17: Khí chuẩn | D17: =SUMIFS('3. TonTheoLo'!$F$5:$F$51,'3. TonTheoLo'!$D$5:$D$51,$A17) -> 0 | E17: =SUMIFS('3. TonTheoLo'!$G$5:$G$51,'3. TonTheoLo'!$D$5:$D$51,$A17) -> 0 | F17: =SUMIFS('3. TonTheoLo'!$H$5:$H$51,'3. TonTheoLo'!$D$5:$D$51,$A17) -> 0 | G17: =SUMIFS('3. TonTheoLo'!$J$5:$J$51,'3. TonTheoLo'!$D$5:$D$51,$A17) -> 0 | H17: 0 | I17: =F17-H17 -> 0
A18: KC-CO-1L | B18: Khí chuẩn | C18: 1L | D18: =SUMIFS('3. TonTheoLo'!$F$5:$F$51,'3. TonTheoLo'!$D$5:$D$51,$A18) -> 1 | E18: =SUMIFS('3. TonTheoLo'!$G$5:$G$51,'3. TonTheoLo'!$D$5:$D$51,$A18) -> 0 | F18: =SUMIFS('3. TonTheoLo'!$H$5:$H$51,'3. TonTheoLo'!$D$5:$D$51,$A18) -> 1 | G18: =SUMIFS('3. TonTheoLo'!$J$5:$J$51,'3. TonTheoLo'!$D$5:$D$51,$A18) -> 3400000 | H18: 0 | I18: =F18-H18 -> 1
A19: KC-CO-1.2L | B19: Khí chuẩn | C19: 1.2L | D19: =SUMIFS('3. TonTheoLo'!$F$5:$F$51,'3. TonTheoLo'!$D$5:$D$51,$A19) -> 0 | E19: =SUMIFS('3. TonTheoLo'!$G$5:$G$51,'3. TonTheoLo'!$D$5:$D$51,$A19) -> 0 | F19: =SUMIFS('3. TonTheoLo'!$H$5:$H$51,'3. TonTheoLo'!$D$5:$D$51,$A19) -> 0 | G19: =SUMIFS('3. TonTheoLo'!$J$5:$J$51,'3. TonTheoLo'!$D$5:$D$51,$A19) -> 0 | H19: 0 | I19: =F19-H19 -> 0
A20: KC-CO-8L | B20: Khí chuẩn | C20: 8L | D20: =SUMIFS('3. TonTheoLo'!$F$5:$F$51,'3. TonTheoLo'!$D$5:$D$51,$A20) -> 1 | E20: =SUMIFS('3. TonTheoLo'!$G$5:$G$51,'3. TonTheoLo'!$D$5:$D$51,$A20) -> 0 | F20: =SUMIFS('3. TonTheoLo'!$H$5:$H$51,'3. TonTheoLo'!$D$5:$D$51,$A20) -> 1 | G20: =SUMIFS('3. TonTheoLo'!$J$5:$J$51,'3. TonTheoLo'!$D$5:$D$51,$A20) -> 6000000 | H20: 0 | I20: =F20-H20 -> 1
A21: KC-CO-10L | B21: Khí chuẩn | C21: 10L | D21: =SUMIFS('3. TonTheoLo'!$F$5:$F$51,'3. TonTheoLo'!$D$5:$D$51,$A21) -> 0 | E21: =SUMIFS('3. TonTheoLo'!$G$5:$G$51,'3. TonTheoLo'!$D$5:$D$51,$A21) -> 0 | F21: =SUMIFS('3. TonTheoLo'!$H$5:$H$51,'3. TonTheoLo'!$D$5:$D$51,$A21) -> 0 | G21: =SUMIFS('3. TonTheoLo'!$J$5:$J$51,'3. TonTheoLo'!$D$5:$D$51,$A21) -> 0 | H21: 0 | I21: =F21-H21 -> 0
A22: KC-CO-20L | B22: Khí chuẩn | C22: 20L | D22: =SUMIFS('3. TonTheoLo'!$F$5:$F$51,'3. TonTheoLo'!$D$5:$D$51,$A22) -> 1 | E22: =SUMIFS('3. TonTheoLo'!$G$5:$G$51,'3. TonTheoLo'!$D$5:$D$51,$A22) -> 0 | F22: =SUMIFS('3. TonTheoLo'!$H$5:$H$51,'3. TonTheoLo'!$D$5:$D$51,$A22) -> 1 | G22: =SUMIFS('3. TonTheoLo'!$J$5:$J$51,'3. TonTheoLo'!$D$5:$D$51,$A22) -> 12000000 | H22: 0 | I22: =F22-H22 -> 1
A23: KC-CO-40L | B23: Khí chuẩn | C23: 40L | D23: =SUMIFS('3. TonTheoLo'!$F$5:$F$51,'3. TonTheoLo'!$D$5:$D$51,$A23) -> 0 | E23: =SUMIFS('3. TonTheoLo'!$G$5:$G$51,'3. TonTheoLo'!$D$5:$D$51,$A23) -> 0 | F23: =SUMIFS('3. TonTheoLo'!$H$5:$H$51,'3. TonTheoLo'!$D$5:$D$51,$A23) -> 0 | G23: =SUMIFS('3. TonTheoLo'!$J$5:$J$51,'3. TonTheoLo'!$D$5:$D$51,$A23) -> 0 | H23: 0 | I23: =F23-H23 -> 0
A24: KC-CO-50L | B24: Khí chuẩn | C24: 50L | D24: =SUMIFS('3. TonTheoLo'!$F$5:$F$51,'3. TonTheoLo'!$D$5:$D$51,$A24) -> 0 | E24: =SUMIFS('3. TonTheoLo'!$G$5:$G$51,'3. TonTheoLo'!$D$5:$D$51,$A24) -> 0 | F24: =SUMIFS('3. TonTheoLo'!$H$5:$H$51,'3. TonTheoLo'!$D$5:$D$51,$A24) -> 0 | G24: =SUMIFS('3. TonTheoLo'!$J$5:$J$51,'3. TonTheoLo'!$D$5:$D$51,$A24) -> 0 | H24: 0 | I24: =F24-H24 -> 0
A25: KC-CO2 | B25: Khí chuẩn | D25: =SUMIFS('3. TonTheoLo'!$F$5:$F$51,'3. TonTheoLo'!$D$5:$D$51,$A25) -> 0 | E25: =SUMIFS('3. TonTheoLo'!$G$5:$G$51,'3. TonTheoLo'!$D$5:$D$51,$A25) -> 0 | F25: =SUMIFS('3. TonTheoLo'!$H$5:$H$51,'3. TonTheoLo'!$D$5:$D$51,$A25) -> 0 | G25: =SUMIFS('3. TonTheoLo'!$J$5:$J$51,'3. TonTheoLo'!$D$5:$D$51,$A25) -> 0 | H25: 0 | I25: =F25-H25 -> 0
A26: KC-CO2-1L | B26: Khí chuẩn | C26: 1L | D26: =SUMIFS('3. TonTheoLo'!$F$5:$F$51,'3. TonTheoLo'!$D$5:$D$51,$A26) -> 1 | E26: =SUMIFS('3. TonTheoLo'!$G$5:$G$51,'3. TonTheoLo'!$D$5:$D$51,$A26) -> 0 | F26: =SUMIFS('3. TonTheoLo'!$H$5:$H$51,'3. TonTheoLo'!$D$5:$D$51,$A26) -> 1 | G26: =SUMIFS('3. TonTheoLo'!$J$5:$J$51,'3. TonTheoLo'!$D$5:$D$51,$A26) -> 3400000 | H26: 0 | I26: =F26-H26 -> 1
A27: KC-CO2-8L | B27: Khí chuẩn | C27: 8L | D27: =SUMIFS('3. TonTheoLo'!$F$5:$F$51,'3. TonTheoLo'!$D$5:$D$51,$A27) -> 0 | E27: =SUMIFS('3. TonTheoLo'!$G$5:$G$51,'3. TonTheoLo'!$D$5:$D$51,$A27) -> 0 | F27: =SUMIFS('3. TonTheoLo'!$H$5:$H$51,'3. TonTheoLo'!$D$5:$D$51,$A27) -> 0 | G27: =SUMIFS('3. TonTheoLo'!$J$5:$J$51,'3. TonTheoLo'!$D$5:$D$51,$A27) -> 0 | H27: 1 | I27: =F27-H27 -> -1
A28: KC-CO2-10L | B28: Khí chuẩn | C28: 10L | D28: =SUMIFS('3. TonTheoLo'!$F$5:$F$51,'3. TonTheoLo'!$D$5:$D$51,$A28) -> 0 | E28: =SUMIFS('3. TonTheoLo'!$G$5:$G$51,'3. TonTheoLo'!$D$5:$D$51,$A28) -> 0 | F28: =SUMIFS('3. TonTheoLo'!$H$5:$H$51,'3. TonTheoLo'!$D$5:$D$51,$A28) -> 0 | G28: =SUMIFS('3. TonTheoLo'!$J$5:$J$51,'3. TonTheoLo'!$D$5:$D$51,$A28) -> 0 | H28: 0 | I28: =F28-H28 -> 0
A29: KC-CO2-40L | B29: Khí chuẩn | C29: 40L | D29: =SUMIFS('3. TonTheoLo'!$F$5:$F$51,'3. TonTheoLo'!$D$5:$D$51,$A29) -> 0 | E29: =SUMIFS('3. TonTheoLo'!$G$5:$G$51,'3. TonTheoLo'!$D$5:$D$51,$A29) -> 0 | F29: =SUMIFS('3. TonTheoLo'!$H$5:$H$51,'3. TonTheoLo'!$D$5:$D$51,$A29) -> 0 | G29: =SUMIFS('3. TonTheoLo'!$J$5:$J$51,'3. TonTheoLo'!$D$5:$D$51,$A29) -> 0 | H29: 0 | I29: =F29-H29 -> 0
A30: KC-ETHANOL-40L | B30: Khí chuẩn | C30: 40L | D30: =SUMIFS('3. TonTheoLo'!$F$5:$F$51,'3. TonTheoLo'!$D$5:$D$51,$A30) -> 0 | E30: =SUMIFS('3. TonTheoLo'!$G$5:$G$51,'3. TonTheoLo'!$D$5:$D$51,$A30) -> 0 | F30: =SUMIFS('3. TonTheoLo'!$H$5:$H$51,'3. TonTheoLo'!$D$5:$D$51,$A30) -> 0 | G30: =SUMIFS('3. TonTheoLo'!$J$5:$J$51,'3. TonTheoLo'!$D$5:$D$51,$A30) -> 0 | H30: 0 | I30: =F30-H30 -> 0
A31: KC-H2-10L | B31: Khí chuẩn | C31: 10L | D31: =SUMIFS('3. TonTheoLo'!$F$5:$F$51,'3. TonTheoLo'!$D$5:$D$51,$A31) -> 0 | E31: =SUMIFS('3. TonTheoLo'!$G$5:$G$51,'3. TonTheoLo'!$D$5:$D$51,$A31) -> 0 | F31: =SUMIFS('3. TonTheoLo'!$H$5:$H$51,'3. TonTheoLo'!$D$5:$D$51,$A31) -> 0 | G31: =SUMIFS('3. TonTheoLo'!$J$5:$J$51,'3. TonTheoLo'!$D$5:$D$51,$A31) -> 0 | H31: 0 | I31: =F31-H31 -> 0
A32: KC-H2S | B32: Khí chuẩn | D32: =SUMIFS('3. TonTheoLo'!$F$5:$F$51,'3. TonTheoLo'!$D$5:$D$51,$A32) -> 0 | E32: =SUMIFS('3. TonTheoLo'!$G$5:$G$51,'3. TonTheoLo'!$D$5:$D$51,$A32) -> 0 | F32: =SUMIFS('3. TonTheoLo'!$H$5:$H$51,'3. TonTheoLo'!$D$5:$D$51,$A32) -> 0 | G32: =SUMIFS('3. TonTheoLo'!$J$5:$J$51,'3. TonTheoLo'!$D$5:$D$51,$A32) -> 0 | H32: 0 | I32: =F32-H32 -> 0
A33: KC-H2S-10L | B33: Khí chuẩn | C33: 10L | D33: =SUMIFS('3. TonTheoLo'!$F$5:$F$51,'3. TonTheoLo'!$D$5:$D$51,$A33) -> 2 | E33: =SUMIFS('3. TonTheoLo'!$G$5:$G$51,'3. TonTheoLo'!$D$5:$D$51,$A33) -> 0 | F33: =SUMIFS('3. TonTheoLo'!$H$5:$H$51,'3. TonTheoLo'!$D$5:$D$51,$A33) -> 2 | G33: =SUMIFS('3. TonTheoLo'!$J$5:$J$51,'3. TonTheoLo'!$D$5:$D$51,$A33) -> 20000000 | H33: 0 | I33: =F33-H33 -> 2
A34: KC-HCL-8L | B34: Khí chuẩn | C34: 8L | D34: =SUMIFS('3. TonTheoLo'!$F$5:$F$51,'3. TonTheoLo'!$D$5:$D$51,$A34) -> 6 | E34: =SUMIFS('3. TonTheoLo'!$G$5:$G$51,'3. TonTheoLo'!$D$5:$D$51,$A34) -> 0 | F34: =SUMIFS('3. TonTheoLo'!$H$5:$H$51,'3. TonTheoLo'!$D$5:$D$51,$A34) -> 6 | G34: =SUMIFS('3. TonTheoLo'!$J$5:$J$51,'3. TonTheoLo'!$D$5:$D$51,$A34) -> 58800000 | H34: 0 | I34: =F34-H34 -> 6
A35: KC-HCL-10L | B35: Khí chuẩn | C35: 10L | D35: =SUMIFS('3. TonTheoLo'!$F$5:$F$51,'3. TonTheoLo'!$D$5:$D$51,$A35) -> 3 | E35: =SUMIFS('3. TonTheoLo'!$G$5:$G$51,'3. TonTheoLo'!$D$5:$D$51,$A35) -> 0 | F35: =SUMIFS('3. TonTheoLo'!$H$5:$H$51,'3. TonTheoLo'!$D$5:$D$51,$A35) -> 3 | G35: =SUMIFS('3. TonTheoLo'!$J$5:$J$51,'3. TonTheoLo'!$D$5:$D$51,$A35) -> 32400000 | H35: 1 | I35: =F35-H35 -> 2
A36: KC-HCL-40L | B36: Khí chuẩn | C36: 40L | D36: =SUMIFS('3. TonTheoLo'!$F$5:$F$51,'3. TonTheoLo'!$D$5:$D$51,$A36) -> 1 | E36: =SUMIFS('3. TonTheoLo'!$G$5:$G$51,'3. TonTheoLo'!$D$5:$D$51,$A36) -> 0 | F36: =SUMIFS('3. TonTheoLo'!$H$5:$H$51,'3. TonTheoLo'!$D$5:$D$51,$A36) -> 1 | G36: =SUMIFS('3. TonTheoLo'!$J$5:$J$51,'3. TonTheoLo'!$D$5:$D$51,$A36) -> 22200000 | H36: 0 | I36: =F36-H36 -> 1
A37: KC-HF-8L | B37: Khí chuẩn | C37: 8L | D37: =SUMIFS('3. TonTheoLo'!$F$5:$F$51,'3. TonTheoLo'!$D$5:$D$51,$A37) -> 8 | E37: =SUMIFS('3. TonTheoLo'!$G$5:$G$51,'3. TonTheoLo'!$D$5:$D$51,$A37) -> 0 | F37: =SUMIFS('3. TonTheoLo'!$H$5:$H$51,'3. TonTheoLo'!$D$5:$D$51,$A37) -> 8 | G37: =SUMIFS('3. TonTheoLo'!$J$5:$J$51,'3. TonTheoLo'!$D$5:$D$51,$A37) -> 88000000 | H37: 1 | I37: =F37-H37 -> 7
A38: KC-HF-10L | B38: Khí chuẩn | C38: 10L | D38: =SUMIFS('3. TonTheoLo'!$F$5:$F$51,'3. TonTheoLo'!$D$5:$D$51,$A38) -> 4 | E38: =SUMIFS('3. TonTheoLo'!$G$5:$G$51,'3. TonTheoLo'!$D$5:$D$51,$A38) -> 0 | F38: =SUMIFS('3. TonTheoLo'!$H$5:$H$51,'3. TonTheoLo'!$D$5:$D$51,$A38) -> 4 | G38: =SUMIFS('3. TonTheoLo'!$J$5:$J$51,'3. TonTheoLo'!$D$5:$D$51,$A38) -> 48400000 | H38: 0 | I38: =F38-H38 -> 4
A39: KC-HF-30L | B39: Khí chuẩn | C39: 30L | D39: =SUMIFS('3. TonTheoLo'!$F$5:$F$51,'3. TonTheoLo'!$D$5:$D$51,$A39) -> 1 | E39: =SUMIFS('3. TonTheoLo'!$G$5:$G$51,'3. TonTheoLo'!$D$5:$D$51,$A39) -> 0 | F39: =SUMIFS('3. TonTheoLo'!$H$5:$H$51,'3. TonTheoLo'!$D$5:$D$51,$A39) -> 1 | G39: =SUMIFS('3. TonTheoLo'!$J$5:$J$51,'3. TonTheoLo'!$D$5:$D$51,$A39) -> 22000000 | H39: 0 | I39: =F39-H39 -> 1
A40: KC-HI-8L | B40: Khí chuẩn | C40: 8L | D40: =SUMIFS('3. TonTheoLo'!$F$5:$F$51,'3. TonTheoLo'!$D$5:$D$51,$A40) -> 0 | E40: =SUMIFS('3. TonTheoLo'!$G$5:$G$51,'3. TonTheoLo'!$D$5:$D$51,$A40) -> 0 | F40: =SUMIFS('3. TonTheoLo'!$H$5:$H$51,'3. TonTheoLo'!$D$5:$D$51,$A40) -> 0 | G40: =SUMIFS('3. TonTheoLo'!$J$5:$J$51,'3. TonTheoLo'!$D$5:$D$51,$A40) -> 0 | H40: 0 | I40: =F40-H40 -> 0
A41: KC-N2 | B41: Khí chuẩn | D41: =SUMIFS('3. TonTheoLo'!$F$5:$F$51,'3. TonTheoLo'!$D$5:$D$51,$A41) -> 0 | E41: =SUMIFS('3. TonTheoLo'!$G$5:$G$51,'3. TonTheoLo'!$D$5:$D$51,$A41) -> 0 | F41: =SUMIFS('3. TonTheoLo'!$H$5:$H$51,'3. TonTheoLo'!$D$5:$D$51,$A41) -> 0 | G41: =SUMIFS('3. TonTheoLo'!$J$5:$J$51,'3. TonTheoLo'!$D$5:$D$51,$A41) -> 0 | H41: 0 | I41: =F41-H41 -> 0
...

Sheet 4. TheoHopDong
A1: GIÁ VỐN HÀNG XUẤT THEO HỢP ĐỒNG BÁN
A2: Tự cộng từ sheet Xuất kho.
A4: MÃ HỢP ĐỒNG | B4: Số bình đã xuất | C4: GIÁ VỐN HÀNG XUẤT | D4: Số lô đã dùng
A5: 876/2025/HĐSXKD-CP | B5: =SUMIFS('2. XuatKho'!$F$5:$F$254,'2. XuatKho'!$D$5:$D$254,$A5) -> 0 | C5: =SUMIFS('2. XuatKho'!$I$5:$I$254,'2. XuatKho'!$D$5:$D$254,$A5) -> 0 | D5: =COUNTIFS('2. XuatKho'!$D$5:$D$254,$A5) -> 0
A6: 2025/2609/OMV - DEAHAN | B6: =SUMIFS('2. XuatKho'!$F$5:$F$254,'2. XuatKho'!$D$5:$D$254,$A6) -> 0 | C6: =SUMIFS('2. XuatKho'!$I$5:$I$254,'2. XuatKho'!$D$5:$D$254,$A6) -> 0 | D6: =COUNTIFS('2. XuatKho'!$D$5:$D$254,$A6) -> 0
A7: 251022/HĐKT/OMV-CNCT | B7: =SUMIFS('2. XuatKho'!$F$5:$F$254,'2. XuatKho'!$D$5:$D$254,$A7) -> 0 | C7: =SUMIFS('2. XuatKho'!$I$5:$I$254,'2. XuatKho'!$D$5:$D$254,$A7) -> 0 | D7: =COUNTIFS('2. XuatKho'!$D$5:$D$254,$A7) -> 0
A8: 251028/HĐKT/OMV-KNK | B8: =SUMIFS('2. XuatKho'!$F$5:$F$254,'2. XuatKho'!$D$5:$D$254,$A8) -> 0 | C8: =SUMIFS('2. XuatKho'!$I$5:$I$254,'2. XuatKho'!$D$5:$D$254,$A8) -> 0 | D8: =COUNTIFS('2. XuatKho'!$D$5:$D$254,$A8) -> 0
A9: 251118/HĐKT/OMV-MTTĐ | B9: =SUMIFS('2. XuatKho'!$F$5:$F$254,'2. XuatKho'!$D$5:$D$254,$A9) -> 0 | C9: =SUMIFS('2. XuatKho'!$I$5:$I$254,'2. XuatKho'!$D$5:$D$254,$A9) -> 0 | D9: =COUNTIFS('2. XuatKho'!$D$5:$D$254,$A9) -> 0
A10: 251118/HĐKT/OMV-MTLA | B10: =SUMIFS('2. XuatKho'!$F$5:$F$254,'2. XuatKho'!$D$5:$D$254,$A10) -> 0 | C10: =SUMIFS('2. XuatKho'!$I$5:$I$254,'2. XuatKho'!$D$5:$D$254,$A10) -> 0 | D10: =COUNTIFS('2. XuatKho'!$D$5:$D$254,$A10) -> 0
A11: 11-18/2/2025/HĐ-KHĐT | B11: =SUMIFS('2. XuatKho'!$F$5:$F$254,'2. XuatKho'!$D$5:$D$254,$A11) -> 0 | C11: =SUMIFS('2. XuatKho'!$I$5:$I$254,'2. XuatKho'!$D$5:$D$254,$A11) -> 0 | D11: =COUNTIFS('2. XuatKho'!$D$5:$D$254,$A11) -> 0
A12: 251203/HĐKT/OMV-HGQ | B12: =SUMIFS('2. XuatKho'!$F$5:$F$254,'2. XuatKho'!$D$5:$D$254,$A12) -> 0 | C12: =SUMIFS('2. XuatKho'!$I$5:$I$254,'2. XuatKho'!$D$5:$D$254,$A12) -> 0 | D12: =COUNTIFS('2. XuatKho'!$D$5:$D$254,$A12) -> 0
A13: 251209/HĐKT/OMV-SESE | B13: =SUMIFS('2. XuatKho'!$F$5:$F$254,'2. XuatKho'!$D$5:$D$254,$A13) -> 0 | C13: =SUMIFS('2. XuatKho'!$I$5:$I$254,'2. XuatKho'!$D$5:$D$254,$A13) -> 0 | D13: =COUNTIFS('2. XuatKho'!$D$5:$D$254,$A13) -> 0
A14: ĐƠN HÀNG NGÀY 13/12/2025-OMV-GPVN | B14: =SUMIFS('2. XuatKho'!$F$5:$F$254,'2. XuatKho'!$D$5:$D$254,$A14) -> 0 | C14: =SUMIFS('2. XuatKho'!$I$5:$I$254,'2. XuatKho'!$D$5:$D$254,$A14) -> 0 | D14: =COUNTIFS('2. XuatKho'!$D$5:$D$254,$A14) -> 0
A15: 251215/HĐKT/OMV-TN | B15: =SUMIFS('2. XuatKho'!$F$5:$F$254,'2. XuatKho'!$D$5:$D$254,$A15) -> 0 | C15: =SUMIFS('2. XuatKho'!$I$5:$I$254,'2. XuatKho'!$D$5:$D$254,$A15) -> 0 | D15: =COUNTIFS('2. XuatKho'!$D$5:$D$254,$A15) -> 0
A16: 251218/HĐKT/OMV-TNK | B16: =SUMIFS('2. XuatKho'!$F$5:$F$254,'2. XuatKho'!$D$5:$D$254,$A16) -> 0 | C16: =SUMIFS('2. XuatKho'!$I$5:$I$254,'2. XuatKho'!$D$5:$D$254,$A16) -> 0 | D16: =COUNTIFS('2. XuatKho'!$D$5:$D$254,$A16) -> 0
... A134: 260821/HĐKT/OMV-TTĐ | B134: =SUMIFS('2. XuatKho'!$F$5:$F$254,'2. XuatKho'!$D$5:$D$254,$A134) -> 0 | C134: =SUMIFS('2. XuatKho'!$I$5:$I$254,'2. XuatKho'!$D$5:$D$254,$A134) -> 0 | D134: =COUNTIFS('2. XuatKho'!$D$5:$D$254,$A134) -> 0
A136: CỘNG | B136: =SUM(B5:B134) -> 0 | C136: =SUM(C5:C134) -> 0 | D136: =SUM(D5:D134) -> 0

Sheet 5. AnhXaTenBan
A1: ÁNH XẠ TÊN HÀNG TRONG HỢP ĐỒNG BÁN → MÃ HÀNG / LÔ
A2: 270 tên khác nhau đang dùng trong 367 dòng hàng của hợp đồng bán. Máy không tự khớp được vì nồng độ ghi tự do — anh gán tay. Riêng 41 dòng dung dịch chuẩn em gán sẵn mã (DD-PH / DD-AMONI / DD-COD / DD-TSS).
A4: Tên hàng trong hợp đồng | B4: Thể tích | C4: Nồng độ ghi trong hợp đồng | D4: Tổng SL đã bán | E4: Số lần xuất hiện | F4: MÃ HÀNG (anh gán) | G4: MÃ LÔ hay dùng (anh gán) | H4: Ghi chú
A5: Bình khí hỗn hợp NO, CO, SO2 | B5: 47L | C5: NO 500ppm CO 300 ppm SO2 300ppm | D5: 22 | E5: 1
A6: Bình khí chuẩn NO2 | C6: 200ppm | D6: 22 | E6: 1
A7: Đồng hồ điều áp | D7: 21 | E7: 6
A8: Bình khí hỗn hợp SO2/NO/CO | B8: 8L | C8: CO 650mg/Nm3 ; SO2 650mg/Nm3 ; NO 980 mg/Nm3 | D8: 16 | E8: 8
A9: Bình khí hỗn hợp NO, SO2, CO | B9: 10L | C9: NO 600ppm CO 300 ppm SO2 600ppm | D9: 16 | E9: 1
A10: Bình khí O2 | B10: 8L | C10: 0.1 | D10: 14 | E10: 12
A11: Khí hỗn hợp SO2/NO/CO | B11: 8L | C11: SO2 650mg/m3; ; NO 980mg/m3; ; CO 650mg/m3 | D11: 12 | E11: 10
A12: Bình khí N2 | B12: 8L | C12: 0.9999 | D12: 12 | E12: 1
A13: Bình khí hiệu chuẩn hỗn hợp SO2/NO/CO | B13: 8L | C13: CO 1000 ppm ; SO2 500 ppm ; NO 1200 ppm | D13: 12 | E13: 2
A14: Bình khí N2 | B14: 10L | C14: 99.99% | D14: 10 | E14: 8
A15: Khí chuẩn O2 | B15: 8L | C15: 0.1 | D15: 9 | E15: 7
A16: Bình khí hỗn hợp SO2/NO/CO | B16: 8L | C16: Nồng độ CO2: 8.02% ; Nồng độ O2: 17% ; | D16: 8 | E16: 1
A17: Bình khí chuẩn HCL | B17: 8L | C17: 100mg/Nm3 | D17: 7 | E17: 1
A18: Khí chuẩn N2 | B18: 10L | C18: 99.99% | D18: 6 | E18: 5
A19: Đầu chuyển đổi | D19: 6 | E19: 1
A20: Bình khí chuẩn O2 | B20: 10L | C20: 0.1 | D20: 6 | E20: 2
A21: Bình khí hỗn hợp SO2/NO/CO | B21: 10L | C21: NO: 1000 mg/Nm3 ; SO2: 1000 mg/Nm3 ; CO: 1000 mg/Nm3 ; | D21: 6 | E21: 2
A22: Bình khí hiệu chuẩn hỗn hợp NO/CO/SO2 | B22: 8L | C22: NO: 469 mg/m3 ; SO2: 1043 mg/m3 ; CO: 368 mg/m3 | D22: 6 | E22: 1
A23: Đồng hồ điều áp+Phụ kiện đi kèm | D23: 6 | E23: 1
A24: Bình Khí HCL | B24: 8L | C24: 100mg/Nm3 | D24: 6 | E24: 2
A25: Khí chuẩn hỗn hợp SO2/NO/CO | B25: 8L | C25: NO: 980 mg/Nm3 ; SO2: 650 mg/Nm3 ; CO: 650 mg/Nm3 | D25: 6 | E25: 3
A26: Bình Khí Chuẩn O2 | B26: 8L | C26: 0.1 | D26: 5 | E26: 1
A27: Bình khí N2 | B27: 10L | C27: 0.9999 | D27: 5 | E27: 5
A28: Khí chuẩn O2 | B28: 8L | C28: 10% | D28: 5 | E28: 5
A29: Khí O2 | B29: 40L | C29: 99.99% | D29: 5 | E29: 1
A30: Khí N2 | B30: 10L | C30: 99.99% | D30: 5 | E30: 4
A31: Khí N2 | B31: 10L | C31: 99.999% | D31: 5 | E31: 1
A32: Khí Oxy tinh khiết | B32: 40L | C32: 99.99% | D32: 5 | E32: 1
A33: Khí chuẩn HCL | B33: 8L | C33: 70mg/m3 | D33: 4 | E33: 4
A34: Khí chuẩn O2 | B34: 10L | C34: 0.1 | D34: 4 | E34: 2
A35: Khí chuẩn NO2 | B35: 1L | C35: 100ppm | D35: 4 | E35: 3
A36: Dung dịch chuẩn TSS | B36: 500ml | C36: 100ml/l | D36: 4 | E36: 1 | F36: DD-TSS | H36: Em gán sẵn theo nhóm dung dịch — anh sửa được
A37: Dung dịch chuẩn TSS | B37: 500ml | C37: 50ml/l | D37: 4 | E37: 1 | F37: DD-TSS | H37: Em gán sẵn theo nhóm dung dịch — anh sửa được
A38: Bình khí N2 | B38: 10L | C38: 99 % | D38: 4 | E38: 1
A39: Bình khí HCL | B39: 10L | C39: 100 mg/3 | D39: 4 | E39: 1
A40: Khí chuẩn SO2 | B40: 8L | C40: 500ppm | D40: 3 | E40: 2
A41: Khí chuẩn NO2 | B41: 8L | C41: 100ppm | D41: 3 | E41: 3
...

Sheet 6. KiemKe
A1: KIỂM KÊ THỰC TẾ 19/08/2026
A2: 95 bình đếm được — chỉ để đối chiếu, không phải dòng nhập.
A4: Nhóm | B4: Tên hàng | C4: Xuất xứ | D4: Thể tích | E4: Nồng độ | F4: Số lượng | G4: MÃ HÀNG (anh gán)
A5: Khí chuẩn | B5: NO2 | C5: Air Liquide | D5: 8L | F5: 1
A6: Khí chuẩn | B6: N2 | C6: Air Liquide | D6: 10L | F6: 8
A7: Khí chuẩn | B7: O2 | C7: Air Liquide | D7: 10L | F7: 1
A8: Khí chuẩn | B8: O2 | C8: Air Liquide | D8: 8L | F8: 5
A9: Khí chuẩn | B9: SO2/NO/CO | C9: Air Liquide | D9: 8L | E9: 650/980/650 | F9: 3
A10: Khí chuẩn | B10: SO2/NO/CO | C10: Air Liquide | D10: 10L | E10: 28,9/306/506 | F10: 1
A11: Khí chuẩn | B11: HF | C11: Air Liquide | D11: 8L | E11: 30 mg/nm3 | F11: 1
A12: Khí chuẩn | B12: NH3 | C12: Air Liquide | D12: 8L | E12: 50,8ppm | F12: 1
A13: Khí chuẩn | B13: HCL | C13: Air Liquide | D13: 10L | E13: 15,2ppm | F13: 1
A14: Khí chuẩn | B14: O2 | D14: 8L | E14: 0.02 | F14: 1
A15: Khí chuẩn | B15: SO2 | D15: 10L | E15: 49,6ppm | F15: 1
A16: Khí chuẩn | B16: CO2 | D16: 8L | E16: 0.0999 | F16: 1
A17: Khí chuẩn | B17: Toàn Tiếng TQ | D17: 10L | F17: 2
A18: Khí chuẩn | B18: SO2/NO/CO | D18: 10L | E18: 500/400/500 | F18: 1
A19: Vỏ bình | B19: Nhôm | D19: 10L | F19: 1
A20: Vỏ bình | B20: Nhôm | D20: 8L | F20: 1
A21: Vỏ bình | B21: Vỏ màu hồng đã kiểm định | D21: 10L | F21: 3
A22: Vỏ bình | B22: Vỏ | D22: 30L | F22: 1
A23: Vỏ bình | B23: Vỏ | D23: 20L | F23: 1
A24: Vỏ bình | B24: Vỏ thép | D24: 10L | F24: 8
A25: Vỏ bình | B25: Vỏ nhôm | D25: 50L | F25: 4
A26: Vỏ bình | B26: Vỏ nhôm | D26: 40L | F26: 1
A27: Vỏ bình | B27: Vỏ thép | D27: 40L | F27: 5
A28: Vỏ bình | B28: Vỏ nhôm | C28: Xịn | D28: 10L | F28: 1
A29: Vỏ bình | B29: Vỏ nhôm | C29: Xịn | D29: 8L | F29: 1
A30: Vỏ bình | B30: Vỏ | D30: 1L | F30: 34
A31: Vỏ bình | B31: Vỏ nhôm | F31: 6
E33: CỘNG | F33: =SUM(F5:F31) -> 95
