Workbook

Sheet Hướng dẫn
A1: APP OXY — DANH SÁCH CHỨC NĂNG THEO SPEC
A2: Căn cứ: "App Oxy - Spec Quản Lý Nội Bộ - rev.md" (Sep 17, 2026). Chi tiết bổ sung tham khảo app đang chạy + tai_lieu/nghiep_vu/.
A4: Sheet | B4: Nội dung
A5: Chức năng theo Spec | B5: 76 chức năng, sắp theo đúng thứ tự module/mục của spec. Mỗi dòng: mô tả chi tiết (trường, màn hình, nút), quy tắc & công thức, quyết định áp dụng, câu hỏi còn mở.
A6: Quyết định đã chốt | B6: 33 điểm spec chưa rõ mà Claude tự quyết, kèm căn cứ. Trạng thái mặc định "Chờ xác nhận" — người phụ trách đổi sang "Đồng ý" hoặc "Cần sửa".
A7: Câu hỏi cần trả lời | B7: 8 điểm chỉ công ty quyết được (dữ liệu thực tế, thoả thuận tiền, quy định nội bộ). Điền vào cột vàng.
A8: Trường dữ liệu | B8: 206 trường của 28 bảng (sheet nguồn trên Google Sheets).
A9: Ma trận quyền | B9: Quyền mặc định vai trò × chức năng (quyết định D-25, chờ xác nhận ở Q-06).
A10: Tổng hợp | B10: Đếm theo module, ưu tiên, tiến độ; số quyết định/câu hỏi theo trạng thái.
A11: Ký hiệu | B11: Ô vàng = người phụ trách điền. Cột "Ghi chú so với app hiện tại" chỉ để tham khảo khi chuyển từ app đang chạy.

Sheet Chức năng theo Spec
A1: CHỨC NĂNG THEO SPEC
A2: Cột "Quyết định" tra ở sheet Quyết định đã chốt; cột "Câu hỏi" tra ở sheet Câu hỏi cần trả lời. Ô vàng: Người phụ trách / Tiến độ.
A4: STT | B4: Mã CN | C4: Module | D4: Mục trong spec | E4: Màn hình / Tab | F4: Tên chức năng | G4: Mô tả chi tiết | H4: Quy tắc nghiệp vụ & công thức | I4: Loại | J4: Bảng dữ liệu | K4: Phụ thuộc | L4: Quyết định | M4: Câu hỏi | N4: Ưu tiên | O4: Ghi chú so với app hiện tại | P4: Người phụ trách | Q4: Tiến độ
A5: 1 | B5: NT-01 | C5: 0. Nền tảng & Kiến trúc | D5: Kiến trúc › Auth.gs | E5: Màn Đăng nhập | F5: Đăng nhập nội bộ bằng email + mật khẩu | G5: • Form: Email, Mật khẩu (nút hiện/ẩn), nút Đăng nhập. • Server kiểm email trong sheet TaiKhoan, so khớp mật khẩu băm (SHA-256 + salt riêng từng tài khoản). • Thành công → tạo token phiên lưu ở PhienDangNhap, trả về client; client lưu token và truyền AUTH_TOKEN tường minh ở MỌI lần gọi server. • Sau đăng nhập: tải danh sách menu theo quyền và prefetch song song dữ liệu các module. | H5: • Token hết hạn sau 12 giờ không hoạt động → bắt đăng nhập lại. • Sai mật khẩu 5 lần liên tiếp → khoá đăng nhập tài khoản 15 phút. • Tài khoản trạng thái "Khoá" không đăng nhập được. • Thông báo lỗi chung "Email hoặc mật khẩu không đúng" (không tiết lộ email có tồn tại). | I5: Hệ thống | J5: TaiKhoan, PhienDangNhap | L5: D-28 | N5: Cao | O5: App hiện tại đăng nhập bằng tên đăng nhập; spec yêu cầu email → làm theo spec.
A6: 2 | B6: NT-02 | C6: 0. Nền tảng & Kiến trúc | D6: Kiến trúc › Auth.gs | E6: Popup Đổi mật khẩu | F6: Đổi mật khẩu & đặt lại mật khẩu | G6: • Người dùng tự đổi: Mật khẩu cũ, Mật khẩu mới, Nhập lại. • Người có quyền Quản lý tài khoản đặt lại mật khẩu cho người khác, tuỳ chọn "Bắt đổi ở lần đăng nhập tới". • Đặt lại mật khẩu → huỷ mọi token phiên của tài khoản đó. | H6: • Mật khẩu mới ≥ 8 ký tự, khác mật khẩu cũ. • Tài khoản có cờ BatDoiMK → sau đăng nhập chỉ hiện popup đổi mật khẩu, chưa vào app. | I6: Hệ thống | J6: TaiKhoan, PhienDangNhap | K6: NT-01 | L6: D-28 | N6: Cao
A7: 3 | B7: NT-03 | C7: 0. Nền tảng & Kiến trúc | D7: Còn cần chốt › Phân quyền | E7: Màn Quản lý tài khoản | F7: Quản lý tài khoản & vai trò | G7: • Danh sách tài khoản: Họ tên, Email, Vai trò, Trạng thái, Lần đăng nhập cuối. • Thêm tài khoản: Họ tên, Email, Vai trò (chọn nhiều), Mật khẩu tạm. • Sửa họ tên/vai trò; Khoá / Mở khoá tài khoản. | H7: • Email duy nhất. • Một người được giữ nhiều vai trò, quyền là hợp của các vai trò. • Không xoá tài khoản đã phát sinh dữ liệu — chỉ Khoá. | I7: Danh mục | J7: TaiKhoan | K7: NT-01 | L7: D-25 | N7: Cao
A8: 4 | B8: NT-04 | C8: 0. Nền tảng & Kiến trúc | D8: Còn cần chốt › Phân quyền + Quy ước code | E8: Toàn app | F8: Phân quyền theo vai trò | G8: • Ma trận quyền mặc định ở sheet "Ma trận quyền" (vai trò × chức năng: Xem / Sửa / Duyệt / —). • Server: mọi hàm ghi dữ liệu gọi _requireCanEdit_ (hoặc _requireOwner_ với bản ghi theo người phụ trách) TRƯỚC khi ghi. • Client: vai trò chỉ-xem ẩn toàn bộ nút hành động (Thêm/Sửa/Lưu/Duyệt/Xoá); menu chỉ hiện module được xem. | H8: • Spec chốt: Sale xem được Khách hàng; Admin xem được Hợp đồng; Kế toán và Giám đốc xem được hết. • Sale chỉ thấy và sửa HĐ Bán do mình phụ trách. • Kiểm tra quyền làm ở server; ẩn nút ở client chỉ là hiển thị. | I8: Hệ thống | J8: TaiKhoan, CauHinh | K8: NT-03 | L8: D-25 | M8: Q-06 | N8: Cao | O8: App hiện tại có 34 khoá quyền × 7 vai trò; spec chỉ nêu quyền xem → ma trận mặc định do Claude đề xuất.
A9: 5 | B9: NT-05 | C9: 0. Nền tảng & Kiến trúc | D9: Kiến trúc › Nền tảng | E9: Index.html | F9: Khung SPA & điều hướng | G9: • 1 trang Index.html chứa các iframe module, giữ sống (kept-alive), không tải lại khi chuyển màn. • navigateTo_(module, {id, tab}) chuyển màn và mở thẳng bản ghi/tab. • Giao tiếp giữa các frame chỉ qua postToAncestors_ / postToDescendantsAndSelf_ (không gọi window.parent.postMessage trực tiếp). • Khi rời màn còn thay đổi chưa lưu → hỏi "Ở lại / Thoát không lưu". | H9: • Hàm nội bộ server đặt hậu tố _. • Dữ liệu dùng chung (danh mục) tải 1 lần, làm mới khi có thay đổi. | I9: Hệ thống | K9: NT-01 | N9: Cao
A10: 6 | B10: NT-06 | C10: 0. Nền tảng & Kiến trúc | D10: Còn cần chốt › Layout UI | E10: Thanh menu | F10: Menu tổng | G10: • Thứ tự: Trang chủ · Hợp đồng bán · Hợp đồng mua · Kho · Kế toán · Phú Tài · Danh mục · Duyệt xoá · Quản lý tài khoản. • Mỗi mục có biểu tượng + nhãn + số đếm việc chờ (VD: phiếu chờ duyệt, yêu cầu xoá chờ duyệt). • Topbar: tên người dùng, vai trò, nút Đổi mật khẩu, Đăng xuất; menu thu gọn (☰) trên màn hẹp. | H10: • Chỉ hiện mục người dùng có quyền Xem. | I10: Giao diện | K10: NT-04, NT-05 | M10: Q-08 | N10: Trung bình
A11: 7 | B11: NT-07 | C11: 0. Nền tảng & Kiến trúc | D11: Còn cần chốt › Layout UI | E11: Trang chủ | F11: Dashboard trang chủ | G11: Các thẻ (mỗi thẻ bấm vào mở màn chi tiết): • Số dư từng Nguồn tiền + tổng. • Tổng Công nợ phải thu / phải trả; số HĐ quá hạn thanh toán. • Số phiếu thu chi / chi phí HĐ đang Chờ duyệt. • HĐ thiếu hồ sơ (chưa lưu / chưa có hoá đơn). • Tồn kho theo kho (tổng số lượng). • Số dư quỹ ảo Phú Tài. • Tạm ứng chưa quyết toán. | H11: • Mỗi vai trò chỉ thấy thẻ thuộc module mình được xem. • Số liệu tính tại thời điểm mở, có nút Làm mới. | I11: Báo cáo | J11: (tổng hợp) | K11: KT-02, KT-17, KT-18, KHO-09, PT-10 | L11: D-26 | M11: Q-08 | N11: Thấp | O11: App hiện tại chưa có dashboard.
A12: 8 | B12: NT-08 | C12: 0. Nền tảng & Kiến trúc | D12: Kiến trúc › Common_CSS/JS + Quy ước UI | E12: Toàn app | F12: Thư viện UI dùng chung | G12: • Common_CSS.html + Common_JS.html là 1 nguồn UI cho mọi module. • Topbar và bộ lọc flex-wrap; thanh tab position:sticky; bảng rộng freeze cột đầu + cuộn ngang. • Font Times New Roman. • Thành phần chung: bảng, form, popup, toast thông báo, ô tiền tệ (định dạng 1.234.567 đ), ô ngày dd/mm/yyyy, ô chọn có tìm kiếm. | H12: • Số tiền hiển thị phân cách hàng nghìn bằng dấu chấm, không thập phân với VNĐ. | I12: Giao diện | M12: Q-08 | N12: Cao | O12: App hiện tại dùng font Be Vietnam Pro; spec yêu cầu Times New Roman.
A13: 9 | B13: NT-09 | C13: 0. Nền tảng & Kiến trúc | D13: Kiến trúc › Quy ước UI | E13: Mọi màn danh sách | F13: Bộ lọc chuẩn | G13: • Ô tìm nhanh free-text (tìm theo số HĐ, tên, MST, nội dung). • Lọc thời gian: Năm / Quý / Tháng. • Lọc multi-select theo trạng thái, người phụ trách, nguồn tiền, kho… tuỳ màn. • Nút Xoá lọc; ghi nhớ bộ lọc gần nhất của người dùng. | H13: • Năm/Quý/Tháng lọc theo ngày chính của màn (Ngày ký với HĐ, Ngày lập với phiếu). | I13: Giao diện | K13: NT-08 | N13: Cao | O13: App hiện tại chỉ có lọc Năm ở Báo cáo.
A14: 10 | B14: NT-10 | C14: 0. Nền tảng & Kiến trúc | D14: Kiến trúc › FieldConfig.gs | E14: Server | F14: Khai báo field tập trung (FieldConfig.gs) | G14: • 1 nguồn khai báo cho mọi bảng: tên field, cột sheet, nhãn hiển thị, kiểu (text/số/tiền/ngày/danh sách/tham chiếu), bắt buộc, danh sách giá trị. • Form và bảng ở client sinh từ khai báo này. | H14: • Cột mới luôn NỐI THÊM vào cuối sheet, không tái dùng cột cũ. • Đổi nhãn không đổi cột. | I14: Hệ thống | J14: Tất cả | N14: Cao
A15: 11 | B15: NT-11 | C15: 0. Nền tảng & Kiến trúc | D15: Kiến trúc › Quy trình duyệt xoá | E15: Mọi màn + màn Duyệt xoá | F15: Quy trình duyệt xoá (Request → Approve) | G15: • Nút Xoá ở mọi bản ghi tạo Yêu cầu xoá: Loại đối tượng, Mã đối tượng, Lý do (bắt buộc). • Màn Duyệt xoá: tab Chờ duyệt / Đã xử lý; cột Ngày gửi, Người gửi, Loại, Đối tượng, Lý do; nút Duyệt / Từ chối. • Người gửi được Rút yêu cầu khi còn Chờ duyệt. | H15: • Không xoá thẳng — kể cả Giám đốc cũng phải tạo yêu cầu rồi duyệt. • Bản ghi đang có yêu cầu xoá hiển thị nhãn "Chờ xoá" và khoá sửa. • Duyệt xoá phiếu đã cộng/trừ số dư hoặc tồn → số dư/tồn tính lại. • Không xoá được bản ghi đang được tham chiếu (VD: HĐ Bán đã có phiếu kho) — phải xoá bản ghi con trước. | I15: Quy trình | J15: YeuCauXoa | K15: NT-04 | N15: Cao | O15: App hiện tại cho người có quyền duyệt xoá được xoá thẳng; spec yêu cầu luôn qua duyệt.
A16: 12 | B16: NT-12 | C16: 0. Nền tảng & Kiến trúc | D16: Module 2 › Tab Lưu trữ hồ sơ | E16: Thành phần dùng chung | F16: Upload & lưu trữ hồ sơ trên Drive | G16: • Upload nhiều file (ảnh, PDF) vào Drive công ty, cây thư mục /App Oxy/Hồ sơ/{Năm}/{Số HĐ}/{Loại hồ sơ}/ do app tự tạo. • Ảnh tự nén (cạnh dài ≤ 2000px) và tạo thumbnail; PDF hiện biểu tượng. • Tải tất cả hồ sơ của 1 HĐ dạng .zip. • Mỗi loại hồ sơ có cờ "Đã lưu" và "Đã scan". | H16: • Upload thành công → tự tích "Đã lưu". • Hồ sơ chỉ có bản giấy → cho tích tay "Đã lưu" kèm ghi chú bắt buộc. • File ≤ 20MB. | I16: Tiện ích | J16: HoSo | K16: NT-05 | L16: D-23 | M16: Q-02 | N16: Cao
A17: 13 | B17: NT-13 | C17: 0. Nền tảng & Kiến trúc | D17: Dữ liệu lịch sử + Còn cần chốt › Import | E17: Công cụ quản trị | F17: Import dữ liệu lịch sử từ 4 file Excel | G17: • Nguồn: THEO DÕI 2026, HỢP ĐỒNG MUA, Bảng kê Thanh Toán, Công nợ Phú Tài Miền Nam. • Bảng mapping cột cũ → field mới cho từng file. • Chạy thử (xem trước, báo dòng lỗi) → Chạy thật. • Import toàn bộ, không nhập tay lại. | H17: • Trường bắt buộc mà dữ liệu cũ thiếu → điền "(Chưa xác định)" và gắn cờ "Dữ liệu import" để lọc bổ sung. • Phiếu thu chi cũ import ở trạng thái Đã duyệt, Người duyệt = "Import". • Chỉ chạy sau khi cấu trúc field (NT-10) đã chốt. | I17: Tiện ích | J17: Tất cả | K17: NT-10 | L17: D-27 | M17: Q-05, Q-07 | N17: Trung bình
A18: 14 | B18: NT-14 | C18: 0. Nền tảng & Kiến trúc | D18: (phục vụ các công thức trong spec) | E18: Màn Cấu hình | F18: Tham số cấu hình | G18: • Các tham số: bậc Thuế TNDN HĐ Bán (ngưỡng 20%, mức 25% / 50%); tỷ lệ Phú Tài (thuế 20%, Phú Tài giữ 10%); tiền tố số phiếu (TC, CP, NK, XK); số đợt thanh toán tối đa (3). • Mỗi lần sửa ghi lại người sửa, thời điểm, giá trị cũ. | H18: • Chỉ Giám đốc sửa. • HĐ đã tính giữ tỷ lệ tại thời điểm tạo; tham số mới chỉ áp cho HĐ tạo sau. | I18: Hệ thống | J18: CauHinh | K18: NT-04 | L18: D-29 | N18: Trung bình
A19: 15 | B19: KT-01 | C19: 1. Kế toán | D19: Module 1 › Danh mục Nguồn tiền | E19: Kế toán › tab Nguồn tiền | F19: Quản lý danh mục Nguồn tiền | G19: • Thẻ cho từng nguồn: Tên, Loại, Số dư hiện tại, dòng tóm tắt "Đầu kỳ · Thu · Chi". • Thêm/Sửa: Mã nguồn, Tên (Tiền mặt, UNC-MSB, UNC-Vietcombank…), Loại (Tiền mặt / Ngân hàng), Số tài khoản + Ngân hàng (nếu Ngân hàng), Số dư đầu kỳ, Ngày đầu kỳ, Trạng thái (Đang dùng / Ngưng). | H19: • Chỉ VNĐ. • Số dư đầu kỳ và Ngày đầu kỳ bị khoá khi nguồn đã có phiếu Đã duyệt. • Nguồn "Ngưng" không hiện trong ô chọn khi lập phiếu mới. • Số dư âm → thẻ hiển thị cảnh báo đỏ. | I19: Danh mục | J19: DM_NguonTien | N19: Cao
A20: 16 | B20: KT-02 | C20: 1. Kế toán | D20: Module 1 › Danh mục Nguồn tiền | E20: Kế toán › tab Nguồn tiền | F20: Tự tính Số dư hiện tại | G20: Số dư hiện tại của 1 nguồn = Số dư đầu kỳ + Σ Số tiền Thu (phiếu Thu, Đã duyệt) − Σ Số tiền Chi (phiếu Chi, Tạm ứng, Đã duyệt) ± Quyết toán tạm ứng (chỉ phần chênh lệch, Đã duyệt) − Σ Luân chuyển đi + Σ Luân chuyển đến (Đã duyệt) − Σ Chi phí thực hiện HĐ (Đã duyệt, chọn nguồn này). | H20: • Phiếu Nháp / Chờ duyệt / Từ chối không tính. • Tính lại ngay khi có phiếu được duyệt hoặc huỷ. | I20: Tự động tính | J20: DM_NguonTien, PhieuThuChi, ChiPhiThucHienHD | K20: KT-01, KT-07, KT-14 | L20: D-13 | N20: Cao
A21: 17 | B21: KT-03 | C21: 1. Kế toán | D21: Còn cần chốt › Loại chi phí | E21: Danh mục › Loại chi phí | F21: Danh mục Loại chi phí (2 nhóm) | G21: • Trường: Mã loại, Tên loại, Nhóm (Vận hành / Thực hiện HĐ), Đang dùng. • Dữ liệu ban đầu: – Vận hành: Văn phòng, Marketing, Lương/Thưởng, Công tác phí. – Thực hiện HĐ: Vận chuyển, Kiểm định, Hoa hồng kinh doanh, Phát sinh khác. | H21: • Sổ Quỹ chung chỉ chọn nhóm Vận hành. • Chi phí thực hiện HĐ chỉ chọn nhóm Thực hiện HĐ. • Không xoá loại đã dùng — chỉ ngưng. | I21: Danh mục | J21: DM_LoaiChiPhi | L21: D-17 | N21: Cao
A22: 18 | B22: KT-04 | C22: 1. Kế toán | D22: Module 1 › Sổ Quỹ chung | E22: Kế toán › tab Sổ quỹ | F22: Danh sách Sổ quỹ | G22: • Cột: Số phiếu, Ngày lập, Loại phiếu, Nguồn tiền, Loại chi phí, Nội dung, Thu, Chi, Người đề nghị, Trạng thái. • Dòng tổng: Tổng Thu, Tổng Chi theo bộ lọc. • Lọc: bộ lọc chuẩn + Loại phiếu, Nguồn tiền, Trạng thái, Loại chi phí. • Chế độ "Xem gộp": thêm các dòng Chi phí thực hiện HĐ đã duyệt (đánh dấu nguồn "CP HĐ") để đối chiếu dòng tiền đầy đủ. • Xuất Excel theo bộ lọc. | H22: • Sổ quỹ không gắn Hợp đồng. • Người không có quyền Kế toán không thấy màn này. | I22: Danh sách | J22: PhieuThuChi | K22: KT-05 | L22: D-14 | N22: Cao
A23: 19 | B23: KT-05 | C23: 1. Kế toán | D23: Module 1 › Sổ Quỹ chung | E23: Popup Lập phiếu | F23: Lập phiếu Thu / Chi | G23: Trường: Số phiếu (tự sinh), Ngày lập, Loại phiếu (Thu / Chi / Tạm ứng / Quyết toán tạm ứng / Luân chuyển), Nguồn tiền, Loại chi phí, Nội dung, Số tiền Thu, Số tiền Chi, Người đề nghị, File đính kèm, Ghi chú. • Nút: Lưu nháp · Gửi duyệt. • In phiếu Thu/Chi (A5). | H23: • Phiếu Thu chỉ nhập Số tiền Thu; phiếu Chi/Tạm ứng chỉ nhập Số tiền Chi; số tiền > 0. • Loại chi phí bắt buộc với Chi và Tạm ứng (nhóm Vận hành). • Chỉ sửa được khi Nháp hoặc Từ chối; Đã duyệt thì khoá (muốn bỏ → yêu cầu xoá). | I23: Nhập liệu | J23: PhieuThuChi | K23: KT-01, KT-03, KT-06 | N23: Cao
A24: 20 | B24: KT-06 | C24: 1. Kế toán | D24: Module 1 › Sổ Quỹ chung | E24: Server | F24: Đánh số phiếu tự động | G24: • Phiếu thu chi: TC{yy}-{nnnn} theo năm của Ngày lập, VD TC26-0001, dùng chung cho mọi loại phiếu. • Chi phí thực hiện HĐ: CP{yy}-{nnnn}. Phiếu kho: NK{yy}-{nnnn} / XK{yy}-{nnnn}. | H24: • Sinh số khi Lưu lần đầu (kể cả Nháp), không tái sử dụng số của phiếu đã xoá. • Sang năm mới đếm lại từ 0001. • Khoá ghi (LockService) khi sinh số để không trùng. | I24: Tự động | J24: PhieuThuChi, ChiPhiThucHienHD, PhieuKho | L24: D-31 | N24: Cao | O24: App hiện tại đánh số PT-/PC-yymm-nnn theo tháng; spec yêu cầu TCyy-nnnn theo năm.
A25: 21 | B25: KT-07 | C25: 1. Kế toán | D25: Module 1 › Sổ Quỹ chung | E25: Kế toán › tab Chờ duyệt | F25: Duyệt / Từ chối phiếu thu chi | G25: • Luồng: Nháp → Chờ duyệt → Đã duyệt / Từ chối. • Tab Chờ duyệt liệt kê phiếu chờ, nút Duyệt / Từ chối (bắt buộc lý do) từng phiếu hoặc chọn nhiều. • Ghi Người duyệt + Ngày duyệt. | H25: • Chỉ phiếu Đã duyệt mới cộng/trừ số dư quỹ. • Người duyệt: vai trò Kế toán hoặc Giám đốc. • Người lập không tự duyệt phiếu của mình (trừ Giám đốc). • Phiếu Từ chối quay về cho người lập sửa và gửi lại. | I25: Quy trình | J25: PhieuThuChi | K25: KT-05, NT-04 | L25: D-10 | N25: Cao | O25: App hiện tại không có bước duyệt phiếu thu chi.
A26: 22 | B26: KT-08 | C26: 1. Kế toán | D26: Module 1 › Sổ Quỹ chung | E26: Popup Lập phiếu | F26: Tạm ứng & Quyết toán tạm ứng | G26: • Phiếu Tạm ứng: như phiếu Chi, thêm Người nhận tạm ứng. • Phiếu Quyết toán tạm ứng: bắt buộc chọn phiếu Tạm ứng gốc (đã duyệt, chưa quyết toán); nhập Số tiền thực chi + Loại chi phí. • Hệ thống tự tính chênh lệch = Tạm ứng − Thực chi. | H26: • Tạm ứng trừ quỹ khi được duyệt. • Quyết toán: chênh lệch > 0 → ghi Thu hoàn ứng vào nguồn; < 0 → ghi Chi bổ sung. Số dư chỉ đổi theo phần chênh lệch. • 1 phiếu Tạm ứng chỉ quyết toán 1 lần. | I26: Nhập liệu | J26: PhieuThuChi | K26: KT-05, KT-07 | L26: D-11 | N26: Trung bình | O26: App hiện tại chưa có loại phiếu này.
A27: 23 | B27: KT-09 | C27: 1. Kế toán | D27: Module 1 › Sổ Quỹ chung | E27: Kế toán › Báo cáo | F27: Báo cáo Tạm ứng chưa quyết toán | G27: • Cột: Người nhận, Số phiếu, Ngày, Số tiền tạm ứng, Số ngày treo. • Nhóm theo người nhận, có tổng. | H27: • Chỉ tính phiếu Tạm ứng Đã duyệt mà chưa có Quyết toán Đã duyệt. | I27: Báo cáo | J27: PhieuThuChi | K27: KT-08 | L27: D-11 | N27: Thấp
A28: 24 | B28: KT-10 | C28: 1. Kế toán | D28: Module 1 › Sổ Quỹ chung (bổ sung Luân chuyển tiền) | E28: Popup Lập phiếu | F28: Luân chuyển tiền giữa các nguồn | G28: • Loại phiếu "Luân chuyển": Nguồn đi, Nguồn đến, Số tiền, Nội dung (VD: Rút tiền ngân hàng nhập quỹ tiền mặt). • 1 phiếu = giảm Nguồn đi + tăng Nguồn đến cùng lúc. | H28: • Nguồn đi ≠ Nguồn đến. • Qua duyệt như phiếu thường. • Không tính vào Tổng Thu/Tổng Chi của báo cáo; tổng số dư mọi nguồn không đổi. | I28: Nhập liệu | J28: PhieuThuChi | K28: KT-05, KT-07 | L28: D-12 | N28: Cao | O28: App hiện tại ghi luân chuyển bằng cặp phiếu thu/chi.
A29: 25 | B29: KT-11 | C29: 1. Kế toán | D29: Module 1 › Sổ Quỹ chung (khớp số dư) | E29: Kế toán › Báo cáo | F29: Báo cáo số dư theo nguồn tại ngày | G29: • Chọn ngày X → bảng: Nguồn tiền, Đầu kỳ, Thu, Chi, Luân chuyển vào/ra, CP HĐ, Số dư tại ngày X. • Ô nhập Số dư thực tế (sao kê / kiểm quỹ) → hiện Chênh lệch. | H29: • Dùng để đối chiếu Số dư Ngân hàng và Tiền mặt với thực tế. • Chênh lệch ≠ 0 → nhắc kiểm tra phiếu thiếu; không tự sinh bút toán điều chỉnh. | I29: Báo cáo | J29: PhieuThuChi, ChiPhiThucHienHD | K29: KT-02 | L29: D-12 | N29: Trung bình
A30: 26 | B30: KT-12 | C30: 1. Kế toán | D30: Module 1 › Chi phí thực hiện HĐ | E30: Kế toán › tab Chi phí HĐ | F30: Danh sách Chi phí thực hiện HĐ | G30: • Cột: Mã CP, Số HĐ, Khách hàng, Ngày, Loại chi phí, Nội dung, Số tiền, Nguồn tiền, Người thực hiện, Trạng thái. • Lọc: bộ lọc chuẩn + Số HĐ, Loại chi phí, Trạng thái. • Tổng số tiền theo bộ lọc. | H30: • Sổ tách riêng, KHÔNG chung bảng với Sổ Quỹ chung. | I30: Danh sách | J30: ChiPhiThucHienHD | K30: KT-13 | N30: Cao | O30: App hiện tại không có sổ riêng; chi phí đi qua hàng chờ rồi thành phiếu chi.
A31: 27 | B31: KT-13 | C31: 1. Kế toán | D31: Module 1 › Chi phí thực hiện HĐ | E31: Popup Nhập chi phí | F31: Nhập Chi phí thực hiện HĐ | G31: Trường: Mã CP (tự sinh), Số HĐ (bắt buộc, chọn từ HopDongBan), Ngày, Loại chi phí thực hiện, Nội dung, Số tiền, Nguồn tiền chi ra, Người thực hiện, Người nhận (bắt buộc nếu Hoa hồng), Đơn vị vận chuyển (nếu Vận chuyển), File đính kèm, Ghi chú. • Nút: Lưu nháp · Gửi duyệt. | H31: • Chỉ chọn Loại chi phí nhóm Thực hiện HĐ. • Số HĐ phải ở trạng thái Hiệu lực trở đi (không phải Báo giá). • Sửa được khi Nháp / Từ chối. | I31: Nhập liệu | J31: ChiPhiThucHienHD | K31: KT-03, HDB-02, KT-01 | L31: D-31 | N31: Cao
A32: 28 | B32: KT-14 | C32: 1. Kế toán | D32: Module 1 › Chi phí thực hiện HĐ | E32: Kế toán › tab Chờ duyệt | F32: Duyệt Chi phí thực hiện HĐ | G32: • Cùng tab Chờ duyệt với phiếu thu chi (lọc theo loại). • Luồng: Nháp → Chờ duyệt → Đã duyệt / Từ chối. | H32: • Đã duyệt → trừ vào số dư Nguồn tiền đã chọn (KT-02) và cộng vào tổng chi phí của HĐ (HDB-11). • Người duyệt theo D-10. | I32: Quy trình | J32: ChiPhiThucHienHD | K32: KT-13, KT-07 | L32: D-10, D-13 | N32: Cao
A33: 29 | B33: KT-15 | C33: 1. Kế toán | D33: Module 1 › Chi phí thực hiện HĐ (bổ sung Hoa hồng) | E33: Popup Nhập chi phí | F33: Hoa hồng kinh doanh của khách | G33: • Ghi là 1 Chi phí thực hiện HĐ loại "Hoa hồng kinh doanh", có Người nhận, Nguồn tiền (thường Tiền mặt). • Liên kết Quỹ nội bộ: khi duyệt trừ thẳng vào Nguồn tiền đã chọn; Sổ quỹ ở chế độ Xem gộp hiển thị dòng này. • "Tiền trả khách" ở Tab 3 HĐ Bán chính là các dòng hoa hồng này. | H33: • KHÔNG tạo thêm phiếu Chi ở Sổ Quỹ chung (tránh trừ quỹ 2 lần). • Cảnh báo nếu tổng hoa hồng của HĐ > Chênh lệch − Thuế TNDN. | I33: Nhập liệu | J33: ChiPhiThucHienHD | K33: KT-13, HDB-09 | L33: D-03, D-14 | N33: Cao
A34: 30 | B34: KT-16 | C34: 1. Kế toán | D34: Module 1 › Chi phí thực hiện HĐ (Quyết toán vận chuyển) | E34: HĐ Bán › Tab 4 / Kế toán › Báo cáo | F34: Quyết toán vận chuyển theo từng HĐ | G34: • Chọn Số HĐ → bảng các chi phí loại Vận chuyển: Ngày, Nội dung, Đơn vị vận chuyển, Số tiền, Nguồn tiền, Trạng thái. • Tổng đã duyệt / chờ duyệt; nút In quyết toán (A4) có chỗ ký Người lập, Kế toán, Giám đốc. | H34: • Lấy từ ChiPhiThucHienHD, không tạo bảng mới, không cần duyệt riêng. | I34: Báo cáo | J34: ChiPhiThucHienHD | K34: KT-13 | L34: D-15 | N34: Trung bình
A35: 31 | B35: KT-17 | C35: 1. Kế toán | D35: Module 1 › Công nợ 2 chiều | E35: Kế toán › tab Công nợ › Phải thu | F35: Báo cáo Công nợ phải thu | G35: • Theo từng HĐ Bán: Số HĐ, Khách hàng, Giá trị sau VAT, Đã thu, Còn phải thu, Hạn đợt gần nhất, Số ngày quá hạn. • Gộp theo khách hàng; tổng toàn bộ. | H35: • Còn phải thu = Giá trị HĐ Bán sau VAT − Σ Số tiền thực thu các đợt. • Không có bảng nhập tay, không có bút toán điều chỉnh rời — muốn sửa thì sửa đợt thanh toán trong HĐ gốc. • Không tính HĐ Báo giá. | I35: Báo cáo | J35: HopDongBan, HopDongBan_DotTT | K35: HDB-10 | N35: Cao
A36: 32 | B36: KT-18 | C36: 1. Kế toán | D36: Module 1 › Công nợ 2 chiều | E36: Kế toán › tab Công nợ › Phải trả | F36: Báo cáo Công nợ phải trả | G36: • Theo từng HĐ Mua: Số HĐ, NCC, Giá trị HĐ, Đã trả, Còn phải trả, Hạn đợt gần nhất. • Gộp theo NCC; tổng toàn bộ. | H36: • Còn phải trả = Giá trị HĐ Mua − Σ Số tiền đã trả NCC các đợt. • Không tính HĐ Mua có cờ "Thuộc Phú Tài". • Không có bút toán điều chỉnh rời. | I36: Báo cáo | J36: HopDongMua, HopDongMua_DotTT | K36: HDM-08 | L36: D-20 | N36: Cao
A37: 33 | B37: HDB-01 | C37: 2. Kinh doanh | D37: Module 2 › HopDongBan | E37: Hợp đồng bán › Danh sách | F37: Danh sách Hợp đồng bán | G37: • Cột: Số HĐ, Khách hàng, Ngày ký, Giá trị sau VAT, Đã thu (%), Còn phải thu, Giao hàng (Chưa/Đang/Đã), Hồ sơ (đủ/thiếu), Sale phụ trách, Trạng thái. • Nút: + Tạo HĐ bán; bấm dòng mở chi tiết 5 tab. • Lọc: bộ lọc chuẩn + Trạng thái, Sale phụ trách, Hồ sơ thiếu. | H37: • Sale chỉ thấy HĐ mình phụ trách; Admin, Kế toán, Giám đốc thấy tất cả. • Trạng thái hiển thị bằng nhãn màu. | I37: Danh sách | J37: HopDongBan | K37: NT-09 | L37: D-25 | N37: Cao
A38: 34 | B38: HDB-02 | C38: 2. Kinh doanh | D38: Module 2 › HopDongBan › Tab 1 | E38: HĐ bán › Tab 1 Thông tin chung | F38: Thông tin chung HĐ Bán | G38: Trường: Số HĐ bán, Khách hàng (chọn từ danh mục, tự điền Tên/MST/Địa chỉ), Ngày ký, Ngày hiệu lực, Trạng thái, Sale phụ trách, Ghi chú. • Nút Lưu; khu "Giao hàng" (HDB-04). | H38: • Số HĐ bán bắt buộc, duy nhất. • Ngày hiệu lực ≥ Ngày ký. • Tên/MST/Địa chỉ lưu bản sao tại thời điểm ký (sửa danh mục không làm đổi HĐ cũ). | I38: Nhập liệu | J38: HopDongBan | K38: HDB-13 | L38: D-24 | N38: Cao
A39: 35 | B39: HDB-03 | C39: 2. Kinh doanh | D39: Module 2 › HopDongBan › Tab 1 | E39: HĐ bán › Tab 1 | F39: Luồng trạng thái HĐ Bán | G39: Báo giá → Hiệu lực → Đang giao hàng → Hoàn thành → Đã tất toán. • Nút chuyển trạng thái kế tiếp; hiển thị điều kiện còn thiếu. | H39: • → Hiệu lực: bắt buộc Số HĐ, Ngày ký, Giá trị HĐ. • → Đang giao hàng: tự chuyển khi có lần giao đầu tiên. • → Hoàn thành: người dùng chuyển khi đã giao đủ. • → Đã tất toán: Còn phải thu = 0 VÀ hồ sơ bắt buộc đã lưu (HĐ, BBGH/BBNT, Hoá đơn) VÀ không còn chi phí Chờ duyệt. • Đã tất toán → khoá toàn bộ HĐ; mở lại chỉ Giám đốc. | I39: Quy trình | J39: HopDongBan | K39: HDB-02, HDB-04, HDB-05, HDB-10 | L39: D-05 | N39: Cao | O39: App hiện tại dùng 4 giai đoạn Báo giá → Chờ HĐ → Đang thực hiện → Kết thúc.
A40: 36 | B40: HDB-04 | C40: 2. Kinh doanh | D40: Module 2 › HopDongBan (đánh dấu đã giao hàng) | E40: HĐ bán › Tab 1 › Giao hàng | F40: Đánh dấu đã giao hàng → sinh phiếu Xuất kho | G40: • Nút "Ghi nhận giao hàng" mở popup: Ngày giao, Vị trí kho (gồm "Chuyển thẳng — không qua kho"), các dòng Loại hàng + thuộc tính + Số lượng (gợi ý sẵn từ HĐ Mua liên quan). • Xác nhận → tự sinh 1 phiếu Xuất kho (Nguồn gốc: Tự động từ HĐ Bán). • Danh sách các lần giao: Ngày, Số phiếu XK, Kho, Số lượng. | H40: • Giao nhiều lần được; mỗi lần = 1 phiếu. • Cảnh báo (không chặn) khi số lượng xuất > tồn tại kho đã chọn. • Huỷ một lần giao = gửi yêu cầu xoá phiếu XK (NT-11). | I40: Tự động | J40: HopDongBan, PhieuKho | K40: HDB-02, KHO-05 | L40: D-06 | N40: Cao
A41: 37 | B41: HDB-05 | C41: 2. Kinh doanh | D41: Module 2 › HopDongBan › Tab 2 | E41: HĐ bán › Tab 2 Lưu trữ hồ sơ | F41: Lưu trữ hồ sơ HĐ Bán | G41: • 4 nhóm: Hợp đồng · BBGH/BBNT · Hoá đơn · Scan hồ sơ khác; mỗi nhóm có vùng upload, thumbnail, cờ Đã lưu / Đã scan. • Ô "Ghi chú hồ sơ thiếu". • Nút Tải tất cả (.zip). | H41: • Bắt buộc có thao tác lưu và scan: thiếu hồ sơ bắt buộc → chặn chuyển "Đã tất toán"; ở "Hoàn thành" chỉ cảnh báo. • Danh sách HĐ hiện nhãn "Thiếu hồ sơ". | I41: Nhập liệu | J41: HoSo | K41: NT-12 | L41: D-23 | M41: Q-02 | N41: Cao
...

Sheet Quyết định đã chốt
A1: QUYẾT ĐỊNH CLAUDE ĐÃ TỰ CHỐT (chờ xác nhận)
A3: Mã | B3: Chủ đề | C3: Spec ghi | D3: Vấn đề | E3: Quyết định | F3: Căn cứ | G3: Áp dụng cho | H3: Trạng thái | I3: Ý kiến
A4: D-01 | B4: Thuế TNDN HĐ Bán | C4: Thuế TNDN 25% trên chênh lệch; ghi chú bổ sung: <20% thu 25%, >20% thu 50% | D4: Không rõ 20% là tỷ lệ của gì, đúng 20% áp mức nào, tính toàn phần hay lũy tiến. | E4: Lũy tiến: phần chênh lệch đến 20% × GTHĐ thực tế trước VAT chịu 25%, phần vượt chịu 50%. Đúng mốc 20% → 25%. Tham số cấu hình được. | F4: App đang chạy tính đúng như vậy (khoản "Phí quản lý"); lũy tiến tránh nhảy bậc đột ngột ở mốc 20%. | G4: HDB-08 | H4: Chờ xác nhận
A5: D-02 | B5: Chênh lệch HĐ Bán | C5: Chênh lệch (tự tính) | D5: Không ghi công thức. | E5: Chênh lệch = Tổng GTHĐ trước VAT − GTHĐ thực tế trước VAT; Tỷ lệ = CL ÷ GTHĐ thực tế. | F5: 2 trường duy nhất spec đặt cạnh Chênh lệch; app đang chạy tính như vậy. | G5: HDB-07 | H5: Chờ xác nhận
A6: D-03 | B6: Tiền trả khách | C6: Tab 3: Tiền trả khách + ngày chi; Module 1: chi phí HĐ có hoa hồng KD của khách, link quỹ | D6: Một khoản ghi ở 2 nơi, có thể trừ quỹ 2 lần. | E6: Tiền trả khách = Hoa hồng KD; lưu 1 nơi ở ChiPhiThucHienHD (loại Hoa hồng), Tab 3 hiển thị + tạo nhanh. | F6: Giữ 1 nguồn dữ liệu, đảm bảo số dư quỹ đúng. | G6: HDB-09, KT-15 | H6: Chờ xác nhận
A7: D-04 | B7: Số đợt thanh toán | C7: Tối đa 3 đợt mỗi HĐ, hiện dần theo đợt | D7: App đang chạy không giới hạn. | E7: Làm theo spec: tối đa 3 đợt (tham số cấu hình được). | F7: Spec ghi rõ. | G7: HDB-10, HDM-08 | H7: Chờ xác nhận
A8: D-05 | B8: Trạng thái HĐ Bán | C8: Báo giá → Hiệu lực → Đang giao hàng → Hoàn thành → Đã tất toán | D8: Chưa có điều kiện chuyển. | E8: Điều kiện như mô tả HDB-03; Đã tất toán khoá HĐ, chỉ Giám đốc mở lại. | F8: Ràng buộc tối thiểu để dữ liệu công nợ/hồ sơ nhất quán. | G8: HDB-03 | H8: Chờ xác nhận
A9: D-06 | B9: Sinh phiếu Xuất kho | C9: Đánh dấu đã giao hàng → tự sinh phiếu Xuất | D9: HĐ Bán không có danh sách hàng nhưng phiếu cần loại hàng, SL, kho. | E9: Popup khi ghi nhận giao: chọn kho + dòng hàng + SL (gợi ý từ HĐ Mua liên quan); mỗi lần giao 1 phiếu; giao nhiều lần được. | F9: Giữ đúng tinh thần "tự sinh" của spec mà vẫn đủ dữ liệu. | G9: HDB-04, KHO-05 | H9: Chờ xác nhận
A10: D-07 | B10: Sinh phiếu Nhập kho | C10: Đánh dấu đã nhập kho ở Tab 3 → tự sinh phiếu Nhập | D10: Theo dòng hay cả HĐ; nhập 1 phần; chọn kho ở đâu. | E10: Theo từng dòng; cho nhập 1 phần; chọn kho trong popup; bỏ nhập qua duyệt xoá. | F10: Thực tế hàng về nhiều đợt (app đang chạy cho nhập 1 phần). | G10: HDM-06, KHO-04 | H10: Chờ xác nhận
A11: D-08 | B11: Trạng thái HĐ Mua | C11: Có trường Trạng thái, không liệt kê | D11: Thiếu danh sách giá trị. | E11: Nháp → Đã ký → Đang nhận hàng → Đã nhận đủ → Đã tất toán (+ Huỷ). | F11: Bám tiến độ nhận hàng và thanh toán của Tab 3/4. | G11: HDM-03 | H11: Chờ xác nhận
A12: D-09 | B12: Trạng thái HĐ Phú Tài | C12: Có trường Trạng thái, không liệt kê | D12: Thiếu danh sách giá trị. | E12: Báo giá → Hiệu lực → Đang thực hiện → Hoàn thành → Đã tất toán (+ Huỷ). | F12: Đồng nhất với HĐ Bán. | G12: PT-03 | H12: Chờ xác nhận
A13: D-10 | B13: Người duyệt | C13: Phiếu duyệt bởi Trưởng phòng/Kế toán | D13: Không có vai trò Trưởng phòng trong danh sách vai trò. | E13: Quyền Duyệt gán cho Kế toán và Giám đốc; người lập không tự duyệt (trừ Giám đốc); chưa đặt hạn mức. | F13: Danh sách vai trò của spec; tách người lập – người duyệt. | G13: KT-07, KT-14 | H13: Chờ xác nhận
A14: D-11 | B14: Tạm ứng / Quyết toán | C14: Loại phiếu có Tạm ứng, Quyết toán tạm ứng | D14: Không mô tả cách tác động số dư. | E14: Tạm ứng trừ quỹ khi duyệt; Quyết toán gắn phiếu gốc, chỉ phần chênh lệch tác động số dư; có báo cáo tạm ứng treo. | F14: Nghiệp vụ tạm ứng chuẩn. | G14: KT-08, KT-09 | H14: Chờ xác nhận
A15: D-12 | B15: Luân chuyển tiền | C15: Bổ sung Luân chuyển tiền; số dư NH và TM phải khớp | D15: Cách ghi nhận chưa chốt. | E15: Loại phiếu Luân chuyển (Nguồn đi + Nguồn đến), qua duyệt; không tính vào Thu/Chi; báo cáo số dư tại ngày để đối chiếu thực tế. | F15: 1 phiếu → không lệch 2 vế. | G15: KT-10, KT-11 | H15: Chờ xác nhận
... A36: D-33 | B36: Quỹ ảo Phú Tài (kỹ thuật) | C36: DongTienPhuTai: Ngày, Chiều, HĐ, Số tiền, Ghi chú | D36: Nhập tay hay tự sinh. | E36: Tự sinh từ Tab 5 (Oxy chuyển PT) + cho nhập tay dòng Điều chỉnh; phần nghĩa của các chiều chờ Q-04. | F36: Không bắt nhập 2 lần. | G36: PT-08, PT-09 | H36: Chờ xác nhận

Sheet Câu hỏi cần trả lời
A1: CÂU HỎI CẦN CÔNG TY TRẢ LỜI
A2: Trả lời từng ý (a), (b)… vào cột Câu trả lời rồi đổi Trạng thái.
A3: Mã | B3: Chủ đề | C3: Vì sao Claude không tự quyết | D3: Câu hỏi | E3: Ảnh hưởng chức năng | F3: Người trả lời | G3: Câu trả lời | H3: Trạng thái
A4: Q-01 | B4: Danh mục Loại hàng | C4: Là dữ liệu thực tế của công ty. | D4: (a) Gửi danh sách Loại hàng / vỏ bình / thiết bị / phụ kiện đang kinh doanh. (b) Các thuộc tính biến thể cần quản lý (nồng độ, thể tích, áp suất, ...)? (c) Có quản lý theo số seri từng vỏ bình không? (d) Đơn vị tính của từng nhóm (bình, cái, bộ...)? | E4: KHO-02, HDM-05, KHO-09 | H4: Chưa trả lời
A5: Q-02 | B5: Drive lưu hồ sơ | C5: Phụ thuộc tài khoản Google của công ty. | D5: (a) Thư mục hồ sơ đặt trong Drive của tài khoản Google nào (chủ sở hữu)? (b) Ai ngoài app được quyền xem thư mục này? | E5: NT-12, HDB-05, HDM-04, PT-02 | H5: Chưa trả lời
A6: Q-03 | B6: Tỷ lệ chia lợi nhuận Phú Tài | C6: Spec và app đang chạy cho kết quả khác nhau, ảnh hưởng tiền thật theo thoả thuận với Phú Tài. | D6: Spec: thuế 20% → Phú Tài giữ 10% của LN sau thuế → Oxy được 72% LN trước thuế. App đang chạy: Phú Tài 10% + thuế 20% đều tính trên chênh lệch → Oxy được 70%. (a) Thoả thuận thực tế với Phú Tài theo cách nào? (b) Nếu theo app, cần sửa bảng công thức Tab 4 của spec. | E6: PT-06, PT-01 | H6: Chưa trả lời
A7: Q-04 | B7: Ý nghĩa quỹ ảo Phú Tài | C7: Là cách công ty theo dõi tiền với Phú Tài. | D7: (a) "Thu về PT" gồm những khoản nào (Oxy chuyển cho PT? khách trả PT phần của Oxy?) (b) "Chi từ PT" gồm những khoản nào (PT trả NCC? PT chuyển lợi nhuận về Oxy?) (c) Khi Phú Tài chuyển lợi nhuận về Oxy, có lập phiếu Thu ở Sổ quỹ Oxy không? | E7: PT-09, PT-10 | H7: Chưa trả lời
A8: Q-05 | B8: Số đợt thanh toán | C8: Spec giới hạn 3 đợt nhưng app đang chạy không giới hạn; dữ liệu cũ có thể có HĐ nhiều đợt hơn. | D8: (a) Có HĐ nào thực tế cần hơn 3 đợt thanh toán không? (b) Nếu có, nâng giới hạn lên bao nhiêu, hay gộp các đợt dư khi import? | E8: HDB-10, HDM-08, NT-13 | H8: Chưa trả lời
A9: Q-06 | B9: Xác nhận ma trận quyền | C9: Là quy định nội bộ về ai được làm gì. | D9: (a) Xác nhận/sửa ma trận ở sheet "Ma trận quyền". (b) Có cần thêm vai trò Mua hàng hoặc Trưởng phòng riêng không? (c) Sale có được xem HĐ của Sale khác không? | E9: NT-04, KT-07, KT-14 | H9: Chưa trả lời
A10: Q-07 | B10: File dữ liệu cũ để import | C10: Cần file gốc mới lập được mapping. | D10: (a) Gửi 4 file: THEO DÕI 2026, HỢP ĐỒNG MUA, Bảng kê Thanh Toán, Công nợ Phú Tài Miền Nam. (b) Dữ liệu từ năm nào trở đi cần import? | E10: NT-13 | H10: Chưa trả lời
A11: Q-08 | B11: Nhận diện thương hiệu | C11: Là tài sản của công ty. | D11: (a) Gửi logo App Oxy (PNG/SVG). (b) Màu chủ đạo của công ty (mã màu) nếu có. | E11: NT-06, NT-07, NT-08 | H11: Chưa trả lời

Sheet Trường dữ liệu
A1: TỪ ĐIỂN TRƯỜNG DỮ LIỆU (mỗi bảng = 1 sheet nguồn)
A3: Bảng | B3: Trường | C3: Kiểu | D3: Bắt buộc | E3: Nguồn / Công thức / Giá trị | F3: Ghi chú
A4: TaiKhoan | B4: Email | C4: Text | D4: Có | E4: Nhập | F4: Duy nhất, dùng để đăng nhập
A5: TaiKhoan | B5: HoTen | C5: Text | D5: Có | E5: Nhập
A6: TaiKhoan | B6: MatKhauBam | C6: Text | D6: Có | E6: SHA-256(mật khẩu + Salt) | F6: Không lưu mật khẩu gốc
A7: TaiKhoan | B7: Salt | C7: Text | D7: Có | E7: Tự sinh
A8: TaiKhoan | B8: VaiTro | C8: Danh sách (nhiều) | D8: Có | E8: Giám đốc / Kế toán / Sale / Admin / Kho / Chỉ xem
A9: TaiKhoan | B9: TrangThai | C9: Danh sách | D9: Có | E9: Hoạt động / Khoá
A10: TaiKhoan | B10: BatDoiMK | C10: Có/Không | F10: Bắt đổi mật khẩu lần đăng nhập tới
A11: TaiKhoan | B11: SoLanSai | C11: Số | E11: Tự đếm | F11: Khoá 15 phút khi = 5
A12: TaiKhoan | B12: LanDangNhapCuoi | C12: Ngày giờ | E12: Tự ghi
A13: PhienDangNhap | B13: Token | C13: Text | D13: Có | E13: Tự sinh
A14: PhienDangNhap | B14: Email | C14: Tham chiếu TaiKhoan | D14: Có
A15: PhienDangNhap | B15: HetHan | C15: Ngày giờ | D15: Có | E15: Lần hoạt động cuối + 12 giờ
A16: CauHinh | B16: Khoa | C16: Text | D16: Có | F16: VD: TNDN_NGUONG, TNDN_MUC1, TNDN_MUC2, PT_THUE, PT_GIU, SO_DOT_TOI_DA
A17: CauHinh | B17: GiaTri | C17: Text/Số | D17: Có
A18: CauHinh | B18: NguoiSua / NgaySua | C18: Text / Ngày giờ | E18: Tự ghi | F18: Lưu lịch sử
A19: YeuCauXoa | B19: MaYC | C19: Text | D19: Có | E19: Tự sinh
A20: YeuCauXoa | B20: LoaiDoiTuong | C20: Danh sách | D20: Có | F20: PhieuThuChi, ChiPhiThucHienHD, HopDongBan, HopDongMua, PhieuKho, HopDongPhuTai, HoSo, DM_*
A21: YeuCauXoa | B21: MaDoiTuong | C21: Text | D21: Có
A22: YeuCauXoa | B22: LyDo | C22: Text | D22: Có | E22: Nhập
A23: YeuCauXoa | B23: NguoiGui / NgayGui | D23: Có | E23: Tự ghi
A24: YeuCauXoa | B24: TrangThai | C24: Danh sách | D24: Có | E24: Chờ duyệt / Đã duyệt / Từ chối / Đã rút
A25: YeuCauXoa | B25: NguoiDuyet / NgayDuyet | E25: Tự ghi
A26: HoSo | B26: MaHoSo | C26: Text | D26: Có | E26: Tự sinh
A27: HoSo | B27: LoaiDoiTuong / SoHD | C27: Text | D27: Có | F27: HĐ Bán / HĐ Mua / HĐ Phú Tài / Phiếu
A28: HoSo | B28: LoaiHoSo | C28: Danh sách | D28: Có | E28: Hợp đồng / BBGH-BBNT / Hoá đơn / Scan khác
A29: HoSo | B29: FileId / Url / Thumbnail | C29: Text | E29: Tự ghi khi upload
A30: HoSo | B30: DaLuu | C30: Có/Không | E30: Tự tích khi upload; tích tay nếu bản giấy
A31: HoSo | B31: DaScan | C31: Có/Không | E31: Nhập
A32: HoSo | B32: GhiChuThieu | C32: Text | E32: Nhập | F32: Bắt buộc khi tích tay DaLuu
A33: HoSo | B33: NguoiUpload / NgayUpload | E33: Tự ghi
A34: HoaDon | B34: LoaiDoiTuong / SoHD | C34: Text | D34: Có
A35: HoaDon | B35: SoHoaDon | C35: Text | D35: Có | E35: Nhập
A36: HoaDon | B36: NgayHoaDon | C36: Ngày | D36: Có | E36: Nhập
A37: HoaDon | B37: GiaTri | C37: Tiền | E37: Nhập | F37: Sau VAT
A38: HoaDon | B38: MaHoSo | C38: Tham chiếu HoSo | F38: File hoá đơn
A39: DM_NguonTien | B39: MaNguon | C39: Text | D39: Có | E39: Nhập | F39: Duy nhất
A40: DM_NguonTien | B40: TenNguon | C40: Text | D40: Có | E40: Nhập
A41: DM_NguonTien | B41: Loai | C41: Danh sách | D41: Có | E41: Tiền mặt / Ngân hàng
...

Sheet Ma trận quyền
A1: MA TRẬN QUYỀN MẶC ĐỊNH (D-25 — chờ xác nhận Q-06)
A2: Căn cứ spec: Sales xem được Khách hàng; Admin xem được Hợp đồng; Kế toán và Giám đốc xem được hết. Phần còn lại Claude đề xuất.
A3: Chức năng | B3: Giám đốc | C3: Kế toán | D3: Sale | E3: Admin | F3: Kho | G3: Chỉ xem
A4: Quản lý tài khoản & phân quyền | B4: Sửa | C4: — | D4: — | E4: — | F4: — | G4: —
A5: Tham số cấu hình | B5: Sửa | C5: Xem | D5: — | E5: — | F5: — | G5: —
A6: Danh mục Nguồn tiền | B6: Sửa | C6: Sửa | D6: — | E6: — | F6: — | G6: Xem
A7: Sổ quỹ — lập phiếu | B7: Sửa | C7: Sửa | D7: Lập đề nghị (Nháp) | E7: Lập đề nghị (Nháp) | F7: — | G7: Xem
A8: Sổ quỹ — duyệt phiếu | B8: Duyệt | C8: Duyệt | D8: — | E8: — | F8: — | G8: —
A9: Chi phí thực hiện HĐ — lập | B9: Sửa | C9: Sửa | D9: Sửa (HĐ của mình) | E9: Sửa | F9: — | G9: Xem
A10: Chi phí thực hiện HĐ — duyệt | B10: Duyệt | C10: Duyệt | D10: — | E10: — | F10: — | G10: —
A11: Công nợ phải thu / phải trả | B11: Xem | C11: Xem | D11: Xem (HĐ của mình) | E11: Xem | F11: — | G11: Xem
A12: Danh mục Khách hàng | B12: Sửa | C12: Xem | D12: Sửa | E12: Sửa | F12: — | G12: Xem
A13: Danh mục Nhà cung cấp | B13: Sửa | C13: Xem | D13: — | E13: Sửa | F13: Xem | G13: Xem
A14: HĐ Bán — Tab 1, 2, 5 | B14: Sửa | C14: Xem | D14: Sửa (HĐ của mình) | E14: Sửa | F14: Xem | G14: Xem
... A26: Dashboard | B26: Xem tất cả thẻ | C26: Thẻ Kế toán, Phú Tài | D26: Thẻ HĐ của mình | E26: Thẻ HĐ, hồ sơ | F26: Thẻ Kho | G26: Xem tất cả thẻ

Sheet Tổng hợp
A1: TỔNG HỢP
A3: Module | B3: Tổng | C3: Ưu tiên Cao | D3: Có câu hỏi mở | E3: Hoàn thành | F3: % Hoàn thành
A4: 0. Nền tảng & Kiến trúc | B4: =COUNTIF('Chức năng theo Spec'!$C$5:$C$80,A4) -> 14 | C4: =COUNTIFS('Chức năng theo Spec'!$C$5:$C$80,A4,'Chức năng theo Spec'!$N$5:$N$80,"Cao") -> 10 | D4: =COUNTIFS('Chức năng theo Spec'!$C$5:$C$80,A4,'Chức năng theo Spec'!$M$5:$M$80,"Q-*") -> 6 | E4: =COUNTIFS('Chức năng theo Spec'!$C$5:$C$80,A4,'Chức năng theo Spec'!$Q$5:$Q$80,"Hoàn thành") -> 0 | F4: =IF(B4=0,0,E4/B4) -> 0
A5: 1. Kế toán | B5: =COUNTIF('Chức năng theo Spec'!$C$5:$C$80,A5) -> 18 | C5: =COUNTIFS('Chức năng theo Spec'!$C$5:$C$80,A5,'Chức năng theo Spec'!$N$5:$N$80,"Cao") -> 14 | D5: =COUNTIFS('Chức năng theo Spec'!$C$5:$C$80,A5,'Chức năng theo Spec'!$M$5:$M$80,"Q-*") -> 0 | E5: =COUNTIFS('Chức năng theo Spec'!$C$5:$C$80,A5,'Chức năng theo Spec'!$Q$5:$Q$80,"Hoàn thành") -> 0 | F5: =IF(B5=0,0,E5/B5) -> 0
A6: 2. Kinh doanh | B6: =COUNTIF('Chức năng theo Spec'!$C$5:$C$80,A6) -> 23 | C6: =COUNTIFS('Chức năng theo Spec'!$C$5:$C$80,A6,'Chức năng theo Spec'!$N$5:$N$80,"Cao") -> 20 | D6: =COUNTIFS('Chức năng theo Spec'!$C$5:$C$80,A6,'Chức năng theo Spec'!$M$5:$M$80,"Q-*") -> 5 | E6: =COUNTIFS('Chức năng theo Spec'!$C$5:$C$80,A6,'Chức năng theo Spec'!$Q$5:$Q$80,"Hoàn thành") -> 0 | F6: =IF(B6=0,0,E6/B6) -> 0
A7: 3. Kho | B7: =COUNTIF('Chức năng theo Spec'!$C$5:$C$80,A7) -> 10 | C7: =COUNTIFS('Chức năng theo Spec'!$C$5:$C$80,A7,'Chức năng theo Spec'!$N$5:$N$80,"Cao") -> 7 | D7: =COUNTIFS('Chức năng theo Spec'!$C$5:$C$80,A7,'Chức năng theo Spec'!$M$5:$M$80,"Q-*") -> 1 | E7: =COUNTIFS('Chức năng theo Spec'!$C$5:$C$80,A7,'Chức năng theo Spec'!$Q$5:$Q$80,"Hoàn thành") -> 0 | F7: =IF(B7=0,0,E7/B7) -> 0
A8: 4. Phú Tài | B8: =COUNTIF('Chức năng theo Spec'!$C$5:$C$80,A8) -> 11 | C8: =COUNTIFS('Chức năng theo Spec'!$C$5:$C$80,A8,'Chức năng theo Spec'!$N$5:$N$80,"Cao") -> 7 | D8: =COUNTIFS('Chức năng theo Spec'!$C$5:$C$80,A8,'Chức năng theo Spec'!$M$5:$M$80,"Q-*") -> 4 | E8: =COUNTIFS('Chức năng theo Spec'!$C$5:$C$80,A8,'Chức năng theo Spec'!$Q$5:$Q$80,"Hoàn thành") -> 0 | F8: =IF(B8=0,0,E8/B8) -> 0
A9: TỔNG | B9: =SUM(B4:B8) -> 76 | C9: =SUM(C4:C8) -> 58 | D9: =SUM(D4:D8) -> 16 | E9: =SUM(E4:E8) -> 0 | F9: =IF(B9=0,0,E9/B9) -> 0
A11: Quyết định / Câu hỏi | B11: Số lượng
A12: Quyết định — Chờ xác nhận | B12: =COUNTIF('Quyết định đã chốt'!$H$4:$H$36,"Chờ xác nhận") -> 33
A13: Quyết định — Đồng ý | B13: =COUNTIF('Quyết định đã chốt'!$H$4:$H$36,"Đồng ý") -> 0
A14: Quyết định — Cần sửa | B14: =COUNTIF('Quyết định đã chốt'!$H$4:$H$36,"Cần sửa") -> 0
A15: Câu hỏi — Chưa trả lời | B15: =COUNTIF('Câu hỏi cần trả lời'!$H$4:$H$11,"Chưa trả lời") -> 8
A16: Câu hỏi — Đã trả lời | B16: =COUNTIF('Câu hỏi cần trả lời'!$H$4:$H$11,"Đã trả lời") -> 0
